Workbook

Sheet Variação do IPCA-15
A1: data | B1: categorias | C1: valor
A2: 43862 | B2: Administrados | C2: 0.03927657
A3: 43862 | B3: Alimentos | C3: -0.02004598
A4: 43862 | B4: Bens Duráveis | C4: 0.0166658
A5: 43862 | B5: Bens Semi/Não Duráveis | C5: -0.11275926
A6: 43862 | B6: Serviços | C6: 0.29678762
A7: 43891 | B7: Administrados | C7: -0.19373245
A8: 43891 | B8: Alimentos | C8: 0.06684702
A9: 43891 | B9: Bens Duráveis | C9: 0.02315238
A10: 43891 | B10: Bens Semi/Não Duráveis | C10: 0.08857781
A11: 43891 | B11: Serviços | C11: 0.03524227
A12: 43922 | B12: Administrados | C12: -0.27059506
A13: 43922 | B13: Alimentos | C13: 0.47599065
... A126: 44593 | B126: Serviços | C126: 0.4669404

Sheet Subitens do IPCA-15
A1: data | B1: itens | C1: variacao_mensal | D1: peso_mensal | E1: ponderado | F1: categorias
A2: 43862 | B2: .ARROZ | C2: 1.02 | D2: 0.4529 | E2: 0.00461958 | F2: Alimentos
A3: 43862 | B3: .FEIJÃO - MULATINHO | C3: -4.87 | D3: 0.0118 | E3: -0.00057466 | F3: Alimentos
A4: 43862 | B4: .FEIJÃO - PRETO | C4: 0.66 | D4: 0.0476 | E4: 0.00031416 | F4: Alimentos
A5: 43862 | B5: .FEIJÃO - MACÁÇAR (FRADINHO) | C5: 8.86 | D5: 0.0145 | E5: 0.0012847 | F5: Alimentos
A6: 43862 | B6: .FEIJÃO - CARIOCA (RAJADO) | C6: -4.44 | D6: 0.1374 | E6: -0.00610056 | F6: Alimentos
A7: 43862 | B7: .MILHO (EM GRÃO) | C7: 1.53 | D7: 0.0103 | E7: 0.00015759 | F7: Alimentos
A8: 43862 | B8: .FARINHA DE ARROZ | C8: -0.75 | D8: 0.0033 | E8: -2.475e-05 | F8: Alimentos
A9: 43862 | B9: .MACARRÃO | C9: 0.1 | D9: 0.1482 | E9: 0.0001482 | F9: Alimentos
A10: 43862 | B10: .FUBÁ DE MILHO | C10: 0.24 | D10: 0.0069 | E10: 1.656e-05 | F10: Alimentos
A11: 43862 | B11: .FLOCOS DE MILHO | C11: 1.74 | D11: 0.0095 | E11: 0.0001653 | F11: Alimentos
A12: 43862 | B12: .FARINHA DE TRIGO | C12: -0.21 | D12: 0.0452 | E12: -9.492e-05 | F12: Alimentos
A13: 43862 | B13: .FARINHA DE MANDIOCA | C13: 3.84 | D13: 0.0918 | E13: 0.00352512 | F13: Alimentos
... A9176: 43952 | B9176: .GASOLINA | C9176: -8.51 | D9176: 4.7884 | E9176: -0.40749284 | F9176: Administrados

Sheet Variação Desagregada do IPCA-15
A1: item | B1: valor | C1: categoria | E1: item | F1: inicio | G1: fim | H1: categoria | I1: id
A2: Emplacamento | B2: 0.03709381 | C2: Administrados | E2: =A2 -> Emplacamento | F2: 0 | G2: =B2 -> 0.03709381 | H2: =C2 -> Administrados | I2: 1
A3: Gasolina | B3: 0.00968175 | C3: Administrados | E3: =A3 -> Gasolina | F3: =G2 -> 0.03709381 | G3: =B3+F3 -> 0.04677556 | H3: =C3 -> Administrados | I3: 2
A4: Óleo Diesel | B4: 0.0091098 | C4: Administrados | E4: =A4 -> Óleo Diesel | F4: =G3 -> 0.04677556 | G4: =B4+F4 -> 0.05588536 | H4: =C4 -> Administrados | I4: 3
A5: Planos de Telefonia | B5: 0.006354 | C5: Administrados | E5: =A5 -> Planos de Telefonia | F5: =G4 -> 0.05588536 | G5: =B5+F5 -> 0.06223936 | H5: =C5 -> Administrados | I5: 4
A6: Água e Esgoto | B6: 0.00555654 | C6: Administrados | E6: =A6 -> Água e Esgoto | F6: =G5 -> 0.06223936 | G6: =B6+F6 -> 0.0677959 | H6: =C6 -> Administrados | I6: 5
A7: Outros1 | B7: ='Variação do IPCA-15'!C122-SUM('Variação Desagregada do IPCA-15'!B2:B6) -> -0.08411078 | C7: Administrados | E7: Outros Administrados | F7: =G6 -> 0.0677959 | G7: =B7+F7 -> -0.01631488 | H7: =C7 -> Administrados | I7: 6
A8: Batata-Inglesa | B8: 0.0316758 | C8: Alimentos | E8: =A8 -> Batata-Inglesa | F8: =G7 -> -0.01631488 | G8: =B8+F8 -> 0.01536092 | H8: =C8 -> Alimentos | I8: 1
A9: Cenoura | B9: 0.02682464 | C9: Alimentos | E9: =A9 -> Cenoura | F9: =G8 -> 0.01536092 | G9: =B9+F9 -> 0.04218556 | H9: =C9 -> Alimentos | I9: 2
A10: Refeição | B10: 0.02094351 | C10: Alimentos | E10: =A10 -> Refeição | F10: =G9 -> 0.04218556 | G10: =B10+F10 -> 0.06312907 | H10: =C10 -> Alimentos | I10: 3
A11: Contrafilé | B11: 0.017978 | C11: Alimentos | E11: =A11 -> Contrafilé | F11: =G10 -> 0.06312907 | G11: =B11+F11 -> 0.08110707 | H11: =C11 -> Alimentos | I11: 4
A12: Alface | B12: 0.0179256 | C12: Alimentos | E12: =A12 -> Alface | F12: =G11 -> 0.08110707 | G12: =B12+F12 -> 0.09903267 | H12: =C12 -> Alimentos | I12: 5
A13: Outros2 | B13: ='Variação do IPCA-15'!C123-SUM('Variação Desagregada do IPCA-15'!B8:B12) -> 0.13273345 | C13: Alimentos | E13: Outros Alimentos | F13: =G12 -> 0.09903267 | G13: =B13+F13 -> 0.23176612 | H13: =C13 -> Alimentos | I13: 6
A14: Automóvel Novo | B14: 0.08185584 | C14: Bens Duráveis | E14: =A14 -> Automóvel Novo | F14: =G13 -> 0.23176612 | G14: =B14+F14 -> 0.31362196 | H14: =C14 -> Bens Duráveis | I14: 1
A15: Automóvel Usado | B15: 0.0408954 | C15: Bens Duráveis | E15: =A15 -> Automóvel Usado | F15: =G14 -> 0.31362196 | G15: =B15+F15 -> 0.35451736 | H15: =C15 -> Bens Duráveis | I15: 2
A16: Refrigerador | B16: 0.0132818 | C16: Bens Duráveis | E16: =A16 -> Refrigerador | F16: =G15 -> 0.35451736 | G16: =B16+F16 -> 0.36779916 | H16: =C16 -> Bens Duráveis | I16: 3
A17: Motocicleta | B17: 0.01267353 | C17: Bens Duráveis | E17: =A17 -> Motocicleta | F17: =G16 -> 0.36779916 | G17: =B17+F17 -> 0.38047269 | H17: =C17 -> Bens Duráveis | I17: 4
A18: Móveis de Quarto | B18: 0.01227393 | C18: Bens Duráveis | E18: =A18 -> Móveis de Quarto | F18: =G17 -> 0.38047269 | G18: =B18+F18 -> 0.39274662 | H18: =C18 -> Bens Duráveis | I18: 5
A19: Outros3 | B19: ='Variação do IPCA-15'!C124-SUM('Variação Desagregada do IPCA-15'!B14:B18) -> 0.06256699 | C19: Bens Duráveis | E19: Outros Duráveis | F19: =G18 -> 0.39274662 | G19: =B19+F19 -> 0.45531361 | H19: =C19 -> Bens Duráveis | I19: 6
A20: Maquiagem | B20: 0.00869778 | C20: Bens Semi/Não Duráveis | E20: =A20 -> Maquiagem | F20: =G19 -> 0.45531361 | G20: =B20+F20 -> 0.46401139 | H20: =C20 -> Bens Semi/Não Duráveis | I20: 1
A21: Camisetas Masculinas | B21: 0.00856422 | C21: Bens Semi/Não Duráveis | E21: =A21 -> Camisetas Masculinas | F21: =G20 -> 0.46401139 | G21: =B21+F21 -> 0.47257561 | H21: =C21 -> Bens Semi/Não Duráveis | I21: 2
A22: Tênis | B22: 0.0082764 | C22: Bens Semi/Não Duráveis | E22: =A22 -> Tênis | F22: =G21 -> 0.47257561 | G22: =B22+F22 -> 0.48085201 | H22: =C22 -> Bens Semi/Não Duráveis | I22: 3
A23: Brinquedo | B23: 0.00720295 | C23: Bens Semi/Não Duráveis | E23: =A23 -> Brinquedo | F23: =G22 -> 0.48085201 | G23: =B23+F23 -> 0.48805496 | H23: =C23 -> Bens Semi/Não Duráveis | I23: 4
A24: Sabonete | B24: 0.00621918 | C24: Bens Semi/Não Duráveis | E24: =A24 -> Sabonete | F24: =G23 -> 0.48805496 | G24: =B24+F24 -> 0.49427414 | H24: =C24 -> Bens Semi/Não Duráveis | I24: 5
A25: Outros4 | B25: ='Variação do IPCA-15'!C125-SUM('Variação Desagregada do IPCA-15'!B20:B24) -> 0.0284982 | C25: Bens Semi/Não Duráveis | E25: Outros Semi/Não Duráveis | F25: =G24 -> 0.49427414 | G25: =B25+F25 -> 0.52277234 | H25: =C25 -> Bens Semi/Não Duráveis | I25: 6
A26: Ensino Fundamental | B26: 0.11560791 | C26: Serviços | E26: =A26 -> Ensino Fundamental | F26: =G25 -> 0.52277234 | G26: =B26+F26 -> 0.63838025 | H26: =C26 -> Serviços | I26: 1
A27: Ensino Superior | B27: 0.0939811 | C27: Serviços | E27: =A27 -> Ensino Superior | F27: =G26 -> 0.63838025 | G27: =B27+F27 -> 0.73236135 | H27: =C27 -> Serviços | I27: 2
A28: Aluguel Residencial | B28: 0.037077 | C28: Serviços | E28: =A28 -> Aluguel Residencial | F28: =G27 -> 0.73236135 | G28: =B28+F28 -> 0.76943835 | H28: =C28 -> Serviços | I28: 3
A29: Ensino Médio | B29: 0.02713948 | C29: Serviços | E29: =A29 -> Ensino Médio | F29: =G28 -> 0.76943835 | G29: =B29+F29 -> 0.79657783 | H29: =C29 -> Serviços | I29: 4
A30: Seguro de Veículos | B30: 0.02638942 | C30: Serviços | E30: =A30 -> Seguro de Veículos | F30: =G29 -> 0.79657783 | G30: =B30+F30 -> 0.82296725 | H30: =C30 -> Serviços | I30: 5
A31: Outros5 | B31: ='Variação do IPCA-15'!C126-SUM('Variação Desagregada do IPCA-15'!B26:B30) -> 0.16674549 | C31: Serviços | E31: Outros Serviços | F31: =G30 -> 0.82296725 | G31: =B31+F31 -> 0.98971274 | H31: =C31 -> Serviços | I31: 6
E32: Total | F32: 0 | G32: =G31 -> 0.98971274 | H32: Total | I32: 31

Sheet Investimento em Carteira
A1: data | B1: total | C1: Renda Variável | D1: Renda Fixa | E1: Fundos
A2: 43831 | B2: 3.3535234 | C2: -1.9023057 | D2: 4.8990495 | E2: 0.35677968
A3: 43862 | B3: -2.7975421 | C3: -4.4275673 | D3: 1.7418008 | E3: -0.11177569
A4: 43891 | B4: -22.261526 | C4: -7.444288 | D4: -14.778385 | E4: -0.038853381
A5: 43922 | B5: -8.2947183 | C5: -2.5581344 | D5: -5.5950707 | E5: -0.14151317
A6: 43952 | B6: -1.5418728 | C6: -1.7088785 | D6: 0.093849628 | E6: 0.073156081
A7: 43983 | B7: 5.5821196 | C7: 0.19205719 | D7: 5.0520275 | E7: 0.3380349
A8: 44013 | B8: -0.95116922 | C8: 0.32967977 | D8: -1.2931997 | E8: 0.012350702
A9: 44044 | B9: 2.1119298 | C9: 0.35419222 | D9: 1.8138828 | E9: -0.056145253
A10: 44075 | B10: 0.87843904 | C10: 0.03535277 | D10: 1.760421 | E10: -0.91733478
A11: 44105 | B11: 5.3360019 | C11: 2.7587767 | D11: 2.4269291 | E11: 0.15029613
A12: 44136 | B12: 7.0520418 | C12: 6.0699959 | D12: 1.5371062 | E12: -0.55506027
A13: 44166 | B13: 9.6523042 | C13: 3.6833054 | D13: 5.6672044 | E13: 0.30179437
... A26: 44562 | B26: 4.8474697 | C26: 1.848433 | D26: 2.6873911 | E26: 0.31164555

Sheet Investimento Direto
A1: data | B1: total | C1: Participação no Capital | D1: Operações Intercompanhias
A2: 43831 | B2: 2.8380689 | C2: 3.1744623 | D2: -0.33639333
A3: 43862 | B3: 2.4560395 | C3: 0.7441329 | D3: 1.7119066
A4: 43891 | B4: 7.8103643 | C4: 4.24593 | D4: 3.5644343
A5: 43922 | B5: 0.97480544 | C5: 0.50517788 | D5: 0.46962756
A6: 43952 | B6: 2.5275737 | C6: 1.9353201 | D6: 0.59225362
A7: 43983 | B7: 4.8874268 | C7: 3.1653678 | D7: 1.722059
A8: 44013 | B8: 4.8277538 | C8: 4.3590399 | D8: 0.46871393
A9: 44044 | B9: 2.046119 | C9: 2.9538469 | D9: -0.90772788
A10: 44075 | B10: 2.8472919 | C10: 2.802782 | D10: 0.044509818
A11: 44105 | B11: 3.1363103 | C11: 4.1660763 | D11: -1.0297661
A12: 44136 | B12: 2.3323722 | C12: 2.2409796 | D12: 0.091392567
A13: 44166 | B13: 1.1021604 | C13: 3.2838481 | D13: -2.1816877
... A26: 44562 | B26: 4.709019 | C26: 4.4021576 | D26: 0.30686135

Sheet Desempenho Cambial
A1: data | B1: Cambio Nominal | C1: Cambio Real (PPC) | D1: menos | E1: mais | F1: dp | G1: IPC BR | H1: IPC US | I1: relacao
A2: 34486 | B2: 1 | C2: =$B$2*I2 -> 1 | D2: =C2 -> 1 | E2: =C2 -> 1 | F2: =C2 -> 1 | G2: 100 | H2: 100 | I2: =G2/H2 -> 1
A3: 34516 | B3: 0.94 | C3: =$B$2*I3 -> 1.0648019 | D3: =C3-F3 -> 1.01898 | E3: =C3+F3 -> 1.1106237 | F3: =_xlfn.STDEV.S($C$2:C3) -> 0.045821831 | G3: 106.84016 | H3: 100.33807 | I3: =G3/H3 -> 1.0648019
A4: 34547 | B4: 0.889 | C4: =$B$2*I4 -> 1.0802439 | D4: =C4-F4 -> 1.0376669 | E4: =C4+F4 -> 1.1228209 | F4: =_xlfn.STDEV.S($C$2:C4) -> 0.042577033 | G4: 108.82782 | H4: 100.74375 | I4: =G4/H4 -> 1.0802439
A5: 34578 | B5: 0.853 | C5: =$B$2*I5 -> 1.0945627 | D5: =C5-F5 -> 1.0528198 | E5: =C5+F5 -> 1.1363056 | F5: =_xlfn.STDEV.S($C$2:C5) -> 0.041742921 | G5: 110.49237 | H5: 100.94659 | I5: =G5/H5 -> 1.0945627
A6: 34608 | B6: 0.846 | C6: =$B$2*I6 -> 1.1224911 | D6: =C6-F6 -> 1.0767709 | E6: =C6+F6 -> 1.1682112 | F6: =_xlfn.STDEV.S($C$2:C6) -> 0.045720115 | G6: 113.38754 | H6: 101.0142 | I6: =G6/H6 -> 1.1224911
A7: 34639 | B7: 0.845 | C7: =$B$2*I7 -> 1.1509459 | D7: =C7-F7 -> 1.0989845 | E7: =C7+F7 -> 1.2029073 | F7: =_xlfn.STDEV.S($C$2:C7) -> 0.051961382 | G7: 116.57315 | H7: 101.28465 | I7: =G7/H7 -> 1.1509459
A8: 34669 | B8: 0.846 | C8: =$B$2*I8 -> 1.1682883 | D8: =C8-F8 -> 1.1114645 | E8: =C8+F8 -> 1.225112 | F8: =_xlfn.STDEV.S($C$2:C8) -> 0.056823736 | G8: 118.56665 | H8: 101.48749 | I8: =G8/H8 -> 1.1682883
A9: 34700 | B9: 0.842 | C9: =$B$2*I9 -> 1.1849915 | D9: =C9-F9 -> 1.1239329 | E9: =C9+F9 -> 1.2460501 | F9: =_xlfn.STDEV.S($C$2:C9) -> 0.061058608 | G9: 120.5823 | H9: 101.75794 | I9: =G9/H9 -> 1.1849915
A10: 34731 | B10: 0.8515 | C10: =$B$2*I10 -> 1.1939005 | D10: =C10-F10 -> 1.1300532 | E10: =C10+F10 -> 1.2577478 | F10: =_xlfn.STDEV.S($C$2:C10) -> 0.063847263 | G10: 121.81176 | H10: 102.0284 | I10: =G10/H10 -> 1.1939005
A11: 34759 | B11: 0.896 | C11: =$B$2*I11 -> 1.2100046 | D11: =C11-F11 -> 1.1431192 | E11: =C11+F11 -> 1.2768899 | F11: =_xlfn.STDEV.S($C$2:C11) -> 0.066885329 | G11: 123.70026 | H11: 102.23124 | I11: =G11/H11 -> 1.2100046
A12: 34790 | B12: 0.913 | C12: =$B$2*I12 -> 1.2345095 | D12: =C12-F12 -> 1.1632593 | E12: =C12+F12 -> 1.3057597 | F12: =_xlfn.STDEV.S($C$2:C12) -> 0.071250167 | G12: 126.70625 | H12: 102.63692 | I12: =G12/H12 -> 1.2345095
A13: 34820 | B13: 0.906 | C13: =$B$2*I13 -> 1.264968 | D13: =C13-F13 -> 1.1876109 | E13: =C13+F13 -> 1.3423251 | F13: =_xlfn.STDEV.S($C$2:C13) -> 0.077357063 | G13: 130.089 | H13: 102.83976 | I13: =G13/H13 -> 1.264968
A14: 34851 | B14: 0.922 | C14: =$B$2*I14 -> 1.2910049 | D14: =C14-F14 -> 1.206921 | E14: =C14+F14 -> 1.3750888 | F14: =_xlfn.STDEV.S($C$2:C14) -> 0.084083911 | G14: 133.0285 | H14: 103.0426 | I14: =G14/H14 -> 1.2910049
... A334: 44593 | B334: 5.01 | C334: =$B$2*I334 -> 3.7781018 | D334: =C334-F334 -> 3.0222553 | E334: =C334+F334 -> 4.5339482 | F334: =_xlfn.STDEV.S($C$2:C334) -> 0.75584644 | G334: 724.84289 | H334: 191.85372 | I334: =G334/H334 -> 3.7781018

Sheet Fluxo Global Total
A1: pais | B1: valor | C1: pib | D1: tipo
A2: United States | B2: 668.061 | C2: 21372.6 | D2: Economia Avançada
A3: Luxembourg | B3: 379.19671 | C3: 71.113 | D3: Economia Avançada
A4: Ireland | B4: 241.0429 | C4: 399.165 | D4: Economia Avançada
A5: United Kingdom | B5: 205.42858 | C5: 2833.301 | D5: Economia Avançada
A6: China | B6: 143.68275 | C6: 14340.6 | D6: Economia Emergente
A7: France | B7: 105.69663 | C7: 2728.834 | D7: Economia Avançada
A8: Canada | B8: 100.91477 | C8: 1741.576 | D8: Economia Avançada
A9: Spain | B9: 86.230916 | C9: 1393.2 | D9: Economia Avançada
A10: Netherlands | B10: 84.368575 | C10: 910.295 | D10: Economia Avançada
A11: Japan | B11: 68.527856 | C11: 5135.896 | D11: Economia Avançada
A12: Belgium | B12: 49.347459 | C12: 533.313 | D12: Economia Avançada
A13: Korea | B13: 45.6585 | C13: 1651.423 | D13: Economia Avançada
... A144: South Africa | B144: -25.813019 | C144: 387.849 | D144: Economia Emergente

Sheet Fluxo Global de Investimentos
A1: pais | B1: valor | C1: tipo | D1: regiao
A2: United States | B2: 668.061 | C2: Economia Avançada | D2: América
A3: Luxembourg | B3: 379.19671 | C3: Economia Avançada | D3: Europa
A4: Ireland | B4: 241.0429 | C4: Economia Avançada | D4: Europa
A5: United Kingdom | B5: 205.42858 | C5: Economia Avançada | D5: Europa
A6: France | B6: 105.69663 | C6: Economia Avançada | D6: Europa
A7: Canada | B7: 100.91477 | C7: Economia Avançada | D7: América
A8: Spain | B8: 86.230916 | C8: Economia Avançada | D8: Europa
A9: Netherlands | B9: 84.368575 | C9: Economia Avançada | D9: Europa
A10: Japan | B10: 68.527856 | C10: Economia Avançada | D10: Ásia
A11: Belgium | B11: 49.347459 | C11: Economia Avançada | D11: Europa
A12: Iceland | B12: 1.1102617 | C12: Economia Avançada | D12: Europa
A13: Estonia | B13: 0.52018402 | C13: Economia Avançada | D13: Europa
... A41: South Africa | B41: -25.813019 | C41: Economia Emergente | D41: África

Sheet Desempenho Cambial Global
A1: data | B1: Brasil | C1: Chile | D1: Peru | E1: Colômbia | F1: México | G1: Bolívia | H1: Uruguai | I1: Argentina | J1: Paraguai | L1: =A1 -> data | M1: Brasil | N1: Chile | O1: Peru | P1: Colômbia | Q1: México | R1: Bolívia | S1: Uruguai | T1: Argentina | U1: Paraguai | W1: =L1 -> data | X1: Brasil | Y1: Média | Z1: menos | AA1: mais | AB1: dp
A2: 44564 | B2: 5.6818 | C2: 851.15 | D2: 3.974 | E2: 4066.6 | F2: 20.494 | G2: 6.895 | H2: 44.69 | I2: 102.9 | J2: 6884 | L2: =A2 -> 44564 | M2: 0 | N2: 0 | O2: 0 | P2: 0 | Q2: 0 | R2: 0 | S2: 0 | T2: 0 | U2: 0 | W2: =L2 -> 44564 | X2: =M2 -> 0 | Y2: =AVERAGE(N2:U2) -> 0 | Z2: =Y2-AB2 -> 0 | AA2: =Y2+AB2 -> 0 | AB2: =X2 -> 0
A3: 44565 | B3: 5.677 | C3: 846.68 | D3: 3.9456 | E3: 4076.8 | F3: 20.501 | G3: 6.905 | H3: 44.61 | I3: 103.09 | J3: 6919.61 | L3: =A3 -> 44565 | M3: =(B3/$B$2-1)*100 -> -0.08448027 | N3: =(C3/$C$2-1)*100 -> -0.52517183 | O3: =(D3/$D$2-1)*100 -> -0.71464519 | P3: =(E3/$E$2-1)*100 -> 0.25082378 | Q3: =(F3/$F$2-1)*100 -> 0.034156338 | R3: =(G3/$G$2-1)*100 -> 0.14503263 | S3: =(H3/$H$2-1)*100 -> -0.17901096 | T3: =(I3/$I$2-1)*100 -> 0.18464529 | U3: =(J3/$J$2-1)*100 -> 0.51728646 | W3: =L3 -> 44565 | X3: =M3 -> -0.08448027 | Y3: =AVERAGE(N3:U3) -> -0.035860435 | Z3: =Y3-AB3 -> -0.44904895 | AA3: =Y3+AB3 -> 0.37732807 | AB3: =_xlfn.STDEV.S(N3:U3) -> 0.41318851
A4: 44566 | B4: 5.7087 | C4: 837.86 | D4: 3.9529 | E4: 4022.1 | F4: 20.565 | G4: 6.895 | H4: 44.73 | I4: 103.04 | J4: 6941 | L4: =A4 -> 44566 | M4: =(B4/$B$2-1)*100 -> 0.47344152 | N4: =(C4/$C$2-1)*100 -> -1.5614169 | O4: =(D4/$D$2-1)*100 -> -0.53095118 | P4: =(E4/$E$2-1)*100 -> -1.0942802 | Q4: =(F4/$F$2-1)*100 -> 0.34644286 | R4: =(G4/$G$2-1)*100 -> 0 | S4: =(H4/$H$2-1)*100 -> 0.089505482 | T4: =(I4/$I$2-1)*100 -> 0.13605442 | U4: =(J4/$J$2-1)*100 -> 0.82800697 | W4: =L4 -> 44566 | X4: =M4 -> 0.47344152 | Y4: =AVERAGE(N4:U4) -> -0.22332982 | Z4: =Y4-AB4 -> -1.0116836 | AA4: =Y4+AB4 -> 0.56502395 | AB4: =_xlfn.STDEV.S(N4:U4) -> 0.78835377
A5: 44567 | B5: 5.6834 | C5: 836.85 | D5: 3.9555 | E5: 4030.51 | F5: 20.486 | G5: 6.885 | H5: 44.73 | I5: 103.22 | J5: 6939.04 | L5: =A5 -> 44567 | M5: =(B5/$B$2-1)*100 -> 0.02816009 | N5: =(C5/$C$2-1)*100 -> -1.6800799 | O5: =(D5/$D$2-1)*100 -> -0.46552592 | P5: =(E5/$E$2-1)*100 -> -0.88747357 | Q5: =(F5/$F$2-1)*100 -> -0.039035815 | R5: =(G5/$G$2-1)*100 -> -0.14503263 | S5: =(H5/$H$2-1)*100 -> 0.089505482 | T5: =(I5/$I$2-1)*100 -> 0.31098154 | U5: =(J5/$J$2-1)*100 -> 0.79953515 | W5: =L5 -> 44567 | X5: =M5 -> 0.02816009 | Y5: =AVERAGE(N5:U5) -> -0.25214071 | Z5: =Y5-AB5 -> -1.0160525 | AA5: =Y5+AB5 -> 0.51177104 | AB5: =_xlfn.STDEV.S(N5:U5) -> 0.76391175
A6: 44568 | B6: 5.6355 | C6: 827.33 | D6: 3.9329 | E6: 4047.06 | F6: 20.36 | G6: 6.895 | H6: 44.73 | I6: 103.285 | J6: 6940.87 | L6: =A6 -> 44568 | M6: =(B6/$B$2-1)*100 -> -0.81488261 | N6: =(C6/$C$2-1)*100 -> -2.7985666 | O6: =(D6/$D$2-1)*100 -> -1.0342224 | P6: =(E6/$E$2-1)*100 -> -0.48049968 | Q6: =(F6/$F$2-1)*100 -> -0.65384991 | R6: =(G6/$G$2-1)*100 -> 0 | S6: =(H6/$H$2-1)*100 -> 0.089505482 | T6: =(I6/$I$2-1)*100 -> 0.37414966 | U6: =(J6/$J$2-1)*100 -> 0.82611854 | W6: =L6 -> 44568 | X6: =M6 -> -0.81488261 | Y6: =AVERAGE(N6:U6) -> -0.45967063 | Z6: =Y6-AB6 -> -1.5745111 | AA6: =Y6+AB6 -> 0.65516987 | AB6: =_xlfn.STDEV.S(N6:U6) -> 1.1148405
A7: 44571 | B7: 5.6633 | C7: 835 | D7: 3.9207 | E7: 4047.06 | F7: 20.36 | G7: 6.885 | H7: 44.52 | I7: 103.45 | J7: 6933 | L7: =A7 -> 44571 | M7: =(B7/$B$2-1)*100 -> -0.32560104 | N7: =(C7/$C$2-1)*100 -> -1.8974329 | O7: =(D7/$D$2-1)*100 -> -1.3412179 | P7: =(E7/$E$2-1)*100 -> -0.48049968 | Q7: =(F7/$F$2-1)*100 -> -0.65384991 | R7: =(G7/$G$2-1)*100 -> -0.14503263 | S7: =(H7/$H$2-1)*100 -> -0.3803983 | T7: =(I7/$I$2-1)*100 -> 0.53449951 | U7: =(J7/$J$2-1)*100 -> 0.71179547 | W7: =L7 -> 44571 | X7: =M7 -> -0.32560104 | Y7: =AVERAGE(N7:U7) -> -0.45651704 | Z7: =Y7-AB7 -> -1.3306153 | AA7: =Y7+AB7 -> 0.41758119 | AB7: =_xlfn.STDEV.S(N7:U7) -> 0.87409823
A8: 44572 | B8: 5.5686 | C8: 827.65 | D8: 3.8956 | E8: 3987.91 | F8: 20.375 | G8: 6.89 | H8: 44.67 | I8: 103.46 | J8: 6935 | L8: =A8 -> 44572 | M8: =(B8/$B$2-1)*100 -> -1.9923264 | N8: =(C8/$C$2-1)*100 -> -2.7609705 | O8: =(D8/$D$2-1)*100 -> -1.9728234 | P8: =(E8/$E$2-1)*100 -> -1.9350317 | Q8: =(F8/$F$2-1)*100 -> -0.58065775 | R8: =(G8/$G$2-1)*100 -> -0.072516316 | S8: =(H8/$H$2-1)*100 -> -0.044752741 | T8: =(I8/$I$2-1)*100 -> 0.54421769 | U8: =(J8/$J$2-1)*100 -> 0.74084834 | W8: =L8 -> 44572 | X8: =M8 -> -1.9923264 | Y8: =AVERAGE(N8:U8) -> -0.76021079 | Z8: =Y8-AB8 -> -2.0599596 | AA8: =Y8+AB8 -> 0.53953798 | AB8: =_xlfn.STDEV.S(N8:U8) -> 1.2997488
A9: 44573 | B9: 5.5338 | C9: 822.97 | D9: 3.8844 | E9: 3970.51 | F9: 20.334 | G9: 6.895 | H9: 44.63 | I9: 103.66 | J9: 6956.85 | L9: =A9 -> 44573 | M9: =(B9/$B$2-1)*100 -> -2.6048083 | N9: =(C9/$C$2-1)*100 -> -3.3108148 | O9: =(D9/$D$2-1)*100 -> -2.2546553 | P9: =(E9/$E$2-1)*100 -> -2.3629076 | Q9: =(F9/$F$2-1)*100 -> -0.78071631 | R9: =(G9/$G$2-1)*100 -> 0 | S9: =(H9/$H$2-1)*100 -> -0.13425822 | T9: =(I9/$I$2-1)*100 -> 0.73858115 | U9: =(J9/$J$2-1)*100 -> 1.058251 | W9: =L9 -> 44573 | X9: =M9 -> -2.6048083 | Y9: =AVERAGE(N9:U9) -> -0.880815 | Z9: =Y9-AB9 -> -2.471617 | AA9: =Y9+AB9 -> 0.70998701 | AB9: =_xlfn.STDEV.S(N9:U9) -> 1.590802
A10: 44574 | B10: 5.5286 | C10: 815.67 | D10: 3.887 | E10: 3963.41 | F10: 20.333 | G10: 6.885 | H10: 44.5 | I10: 103.76 | J10: 6949.88 | L10: =A10 -> 44574 | M10: =(B10/$B$2-1)*100 -> -2.6963286 | N10: =(C10/$C$2-1)*100 -> -4.1684779 | O10: =(D10/$D$2-1)*100 -> -2.18923 | P10: =(E10/$E$2-1)*100 -> -2.5375006 | Q10: =(F10/$F$2-1)*100 -> -0.78559578 | R10: =(G10/$G$2-1)*100 -> -0.14503263 | S10: =(H10/$H$2-1)*100 -> -0.42515104 | T10: =(I10/$I$2-1)*100 -> 0.83576288 | U10: =(J10/$J$2-1)*100 -> 0.95700174 | W10: =L10 -> 44574 | X10: =M10 -> -2.6963286 | Y10: =AVERAGE(N10:U10) -> -1.0572779 | Z10: =Y10-AB10 -> -2.8340508 | AA10: =Y10+AB10 -> 0.71949497 | AB10: =_xlfn.STDEV.S(N10:U10) -> 1.7767729
A11: 44575 | B11: 5.5344 | C11: 818.88 | D11: 3.866 | E11: 4003.26 | F11: 20.29 | G11: 6.895 | H11: 44.56 | I11: 103.84 | J11: 6969.54 | L11: =A11 -> 44575 | M11: =(B11/$B$2-1)*100 -> -2.5942483 | N11: =(C11/$C$2-1)*100 -> -3.7913411 | O11: =(D11/$D$2-1)*100 -> -2.7176648 | P11: =(E11/$E$2-1)*100 -> -1.5575665 | Q11: =(F11/$F$2-1)*100 -> -0.99541329 | R11: =(G11/$G$2-1)*100 -> 0 | S11: =(H11/$H$2-1)*100 -> -0.29089282 | T11: =(I11/$I$2-1)*100 -> 0.91350826 | U11: =(J11/$J$2-1)*100 -> 1.2425915 | W11: =L11 -> 44575 | X11: =M11 -> -2.5942483 | Y11: =AVERAGE(N11:U11) -> -0.89959735 | Z11: =Y11-AB11 -> -2.6384713 | AA11: =Y11+AB11 -> 0.83927656 | AB11: =_xlfn.STDEV.S(N11:U11) -> 1.7388739
A12: 44578 | B12: 5.5165 | C12: 821.68 | D12: 3.8424 | E12: 4003.26 | F12: 20.281 | G12: 6.895 | H12: 44.56 | I12: 104.02 | J12: 6957.86 | L12: =A12 -> 44578 | M12: =(B12/$B$2-1)*100 -> -2.9092893 | N12: =(C12/$C$2-1)*100 -> -3.4623744 | O12: =(D12/$D$2-1)*100 -> -3.3115249 | P12: =(E12/$E$2-1)*100 -> -1.5575665 | Q12: =(F12/$F$2-1)*100 -> -1.0393286 | R12: =(G12/$G$2-1)*100 -> 0 | S12: =(H12/$H$2-1)*100 -> -0.29089282 | T12: =(I12/$I$2-1)*100 -> 1.0884354 | U12: =(J12/$J$2-1)*100 -> 1.0729227 | W12: =L12 -> 44578 | X12: =M12 -> -2.9092893 | Y12: =AVERAGE(N12:U12) -> -0.93754115 | Z12: =Y12-AB12 -> -2.7042596 | AA12: =Y12+AB12 -> 0.82917726 | AB12: =_xlfn.STDEV.S(N12:U12) -> 1.7667184
A13: 44579 | B13: 5.5666 | C13: 817.08 | D13: 3.8597 | E13: 4033.2 | F13: 20.396 | G13: 6.89 | H13: 44.56 | I13: 104.06 | J13: 6959 | L13: =A13 -> 44579 | M13: =(B13/$B$2-1)*100 -> -2.0275265 | N13: =(C13/$C$2-1)*100 -> -4.0028197 | O13: =(D13/$D$2-1)*100 -> -2.8761953 | P13: =(E13/$E$2-1)*100 -> -0.82132494 | Q13: =(F13/$F$2-1)*100 -> -0.47818874 | R13: =(G13/$G$2-1)*100 -> -0.072516316 | S13: =(H13/$H$2-1)*100 -> -0.29089282 | T13: =(I13/$I$2-1)*100 -> 1.1273081 | U13: =(J13/$J$2-1)*100 -> 1.0894829 | W13: =L13 -> 44579 | X13: =M13 -> -2.0275265 | Y13: =AVERAGE(N13:U13) -> -0.79064336 | Z13: =Y13-AB13 -> -2.5932226 | AA13: =Y13+AB13 -> 1.0119358 | AB13: =_xlfn.STDEV.S(N13:U13) -> 1.8025792
A14: 44580 | B14: 5.4383 | C14: 808.18 | D14: 3.8554 | E14: 3990.36 | F14: 20.502 | G14: 6.885 | H14: 44.57 | I14: 104.14 | J14: 6959 | L14: =A14 -> 44580 | M14: =(B14/$B$2-1)*100 -> -4.2856137 | N14: =(C14/$C$2-1)*100 -> -5.0484638 | O14: =(D14/$D$2-1)*100 -> -2.9843986 | P14: =(E14/$E$2-1)*100 -> -1.8747848 | Q14: =(F14/$F$2-1)*100 -> 0.039035815 | R14: =(G14/$G$2-1)*100 -> -0.14503263 | S14: =(H14/$H$2-1)*100 -> -0.26851645 | T14: =(I14/$I$2-1)*100 -> 1.2050534 | U14: =(J14/$J$2-1)*100 -> 1.0894829 | W14: =L14 -> 44580 | X14: =M14 -> -4.2856137 | Y14: =AVERAGE(N14:U14) -> -0.99845303 | Z14: =Y14-AB14 -> -3.1587096 | AA14: =Y14+AB14 -> 1.1618035 | AB14: =_xlfn.STDEV.S(N14:U14) -> 2.1602566
... A46: 44624 | B46: 5.062 | C46: 806.11 | D46: 3.7512 | E46: 3826.01 | F46: 20.935 | G46: 6.885 | H46: 42.57 | I46: 108.02 | J46: 6960 | L46: =A46 -> 44624 | M46: =(B46/$B$2-1)*100 -> -10.908515 | N46: =(C46/$C$2-1)*100 -> -5.2916642 | O46: =(D46/$D$2-1)*100 -> -5.6064419 | P46: =(E46/$E$2-1)*100 -> -5.9162445 | Q46: =(F46/$F$2-1)*100 -> 2.1518493 | R46: =(G46/$G$2-1)*100 -> -0.14503263 | S46: =(H46/$H$2-1)*100 -> -4.7437906 | T46: =(I46/$I$2-1)*100 -> 4.9757046 | U46: =(J46/$J$2-1)*100 -> 1.1040093 | W46: =L46 -> 44624 | X46: =M46 -> -10.908515 | Y46: =AVERAGE(N46:U46) -> -1.6839513 | Z46: =Y46-AB46 -> -5.9077246 | AA46: =Y46+AB46 -> 2.5398219 | AB46: =_xlfn.STDEV.S(N46:U46) -> 4.2237733

Sheet Expectativas IPCA - Rascunho
A1: data | B1: Alimentos | E1: Transportes | H1: Saúde | K1: Despesas Pessoais | N1: Habitação | Q1: Residência | T1: Educação | W1: Comunicação | Z1: Vestuário
B2: Base | C2: Otimista | D2: Pessimista | E2: Base | F2: Otimista | G2: Pessimista | H2: Base | I2: Otimista | J2: Pessimista | K2: Base | L2: Otimista | M2: Pessimista | N2: Base | O2: Otimista | P2: Pessimista | Q2: Base | R2: Otimista | S2: Pessimista | T2: Base | U2: Otimista | V2: Pessimista | W2: Base | X2: Otimista | Y2: Pessimista | Z2: Base | AA2: Otimista | AB2: Pessimista
A3: 44593 | B3: 0.85704406 | C3: 0.42841792 | D3: 1.2856702 | E3: 0.32582383 | F3: -0.21447613 | G3: 0.86612379 | H3: 0.47732045 | I3: 0.24797199 | J3: 0.70666892 | K3: 0.35911614 | L3: 0.077091523 | M3: 0.64114075 | N3: 0.46180284 | O3: 0.0056940019 | P3: 0.91791168 | Q3: 1.2884769 | R3: 1.0203033 | S3: 1.5566505 | T3: 2.7734956 | U3: 2.4467406 | V3: 3.1002506 | W3: 0.074640491 | X3: -0.3879798 | Y3: 0.53726078 | Z3: 0.82789334 | AA3: 0.574009 | AB3: 1.0817777
A4: 44621 | B4: 0.70429932 | C4: 0.17770175 | D4: 1.2308969 | E4: 0.60046334 | F4: 0.0068364 | G4: 1.1940903 | H4: 0.24309911 | I4: -0.0031744888 | J4: 0.48937271 | K4: 0.2832502 | L4: -0.0023220326 | M4: 0.56882243 | N4: 0.42403809 | O4: -0.036701816 | P4: 0.88477799 | Q4: 1.177627 | R4: 0.87557767 | S4: 1.4796763 | T4: -0.25131313 | U4: -0.57906184 | V4: 0.076435578 | W4: 0.065769139 | X4: -0.40080554 | Y4: 0.53234382 | Z4: 1.188799 | AA4: 0.92706181 | AB4: 1.4505362
A5: 44652 | B5: 0.66198326 | C5: 0.11314714 | D5: 1.2108194 | E5: 0.76127518 | F5: 0.1571904 | G5: 1.36536 | H5: 0.57187304 | I5: 0.32452952 | J5: 0.81921656 | K5: 0.28761866 | L5: 0.0020433696 | M5: 0.57319395 | N5: 0.46694077 | O5: -0.0061436099 | P5: 0.94002515 | Q5: 1.0397759 | R5: 0.71636717 | S5: 1.3631847 | T5: 0.012615858 | U5: -0.31513889 | V5: 0.34037061 | W5: -0.03618657 | X5: -0.50602915 | Y5: 0.43365601 | Z5: 1.2221046 | AA5: 0.95359692 | AB5: 1.4906122
A6: 44682 | B6: 0.63070924 | C6: 0.076333042 | D6: 1.1850854 | E6: 0.64166002 | F6: 0.035431556 | G6: 1.2478885 | H6: 0.45238886 | I6: 0.20282106 | J6: 0.70195667 | K6: 0.33453196 | L6: 0.048211279 | M6: 0.62085263 | N6: 0.45412653 | O6: -0.019867256 | P6: 0.92812032 | Q6: 0.99798846 | R6: 0.66059761 | S6: 1.3353793 | T6: 0.041487636 | U6: -0.28626715 | V6: 0.36924242 | W6: 0.23674651 | X6: -0.23397285 | Y6: 0.70746588 | Z6: 1.3033515 | AA6: 1.0289807 | AB6: 1.5777223
A7: 44713 | B7: 0.61180436 | C7: 0.056021222 | D7: 1.1675875 | E7: 0.34889245 | F7: -0.2577791 | G7: 0.955564 | H7: 0.44542088 | I7: 0.19469129 | J7: 0.69615047 | K7: 0.37007456 | L7: 0.083745614 | M7: 0.6564035 | N7: 0.4908173 | O7: 0.01603941 | P7: 0.96559518 | Q7: 0.8626525 | R7: 0.5159213 | S7: 1.2093837 | T7: 0.032773598 | U7: -0.29498119 | V7: 0.36052839 | W7: 0.088915699 | X7: -0.38262193 | Y7: 0.56045333 | Z7: 1.1773129 | AA7: 0.89784657 | AB7: 1.4567793
A8: 44743 | B8: 0.62017572 | C8: 0.064033594 | D8: 1.1763178 | E8: 0.40901244 | F8: -0.19775085 | G8: 1.0157757 | H8: 0.061997372 | I8: -0.18962741 | J8: 0.31362216 | K8: 0.41132002 | L8: 0.12444415 | M8: 0.69819588 | N8: 0.6014254 | O8: 0.12653783 | P8: 1.076313 | Q8: 0.75108457 | R8: 0.39803812 | S8: 1.104131 | T8: 0.087187485 | U8: -0.2405673 | V8: 0.41494227 | W8: 0.2233752 | X8: -0.24873777 | Y8: 0.69548816 | Z8: 0.55968327 | AA8: 0.27577557 | AB8: 0.84359097
A9: 44774 | B9: 0.69651387 | C9: 0.14028004 | D9: 1.2527477 | E9: 0.52605089 | F9: -0.080731404 | G9: 1.1328332 | H9: 0.28558614 | I9: 0.03335353 | J9: 0.53781876 | K9: 0.47555777 | L9: 0.18864425 | M9: 0.76247128 | N9: 0.54149084 | O9: 0.066546831 | P9: 1.0164348 | Q9: 0.74155465 | R9: 0.38420586 | S9: 1.0989034 | T9: -0.85788137 | U9: -1.1856362 | V9: -0.53012658 | W9: 0.24593166 | X9: -0.22733278 | Y9: 0.7191961 | Z9: 0.98720671 | AA9: 0.69941854 | AB9: 1.2749949
A10: 44805 | B10: 0.65631039 | C10: 0.10005313 | D10: 1.2125677 | E10: 0.43008526 | F10: -0.17670097 | G10: 1.0368715 | H10: 0.23802969 | I10: -0.014633025 | J10: 0.49069241 | K10: 0.44275617 | L10: 0.1554174 | M10: 0.73009494 | N10: 0.53520752 | O10: 0.060252461 | P10: 1.0101626 | Q10: 0.6562495 | R10: 0.29595526 | S10: 1.0165437 | T10: -0.0509797 | U10: -0.37873449 | V10: 0.27677509 | W10: 0.23383862 | X10: -0.2398731 | Y10: 0.70755034 | Z10: 0.90108251 | AA10: 0.60989708 | AB10: 1.192268
A11: 44835 | B11: 0.67050484 | C11: 0.1142416 | D11: 1.2267681 | E11: 0.46394161 | F11: -0.14284543 | G11: 1.0707286 | H11: 0.39933702 | I11: 0.14637369 | J11: 0.65230034 | K11: 0.50476511 | L11: 0.21735516 | M11: 0.79217505 | N11: 0.52130575 | O11: 0.046346317 | P11: 0.99626517 | Q11: 0.66743349 | R11: 0.30511619 | S11: 1.0297508 | T11: 0.019471492 | U11: -0.3082833 | V11: 0.34722628 | W11: 0.58969787 | X11: 0.11563925 | Y11: 1.0637565 | Z11: 1.6647902 | AA11: 1.3706255 | AB11: 1.9589549
A12: 44866 | B12: 0.54599263 | C12: -0.010272149 | D12: 1.1022574 | E12: 0.52850545 | F12: -0.078281727 | G12: 1.1352926 | H12: -0.0032973838 | I12: -0.25647178 | J12: 0.24987701 | K12: 0.44812996 | L12: 0.16037154 | M12: 0.73588838 | N12: 0.54620224 | O12: 0.071241781 | P12: 1.0211627 | Q12: 0.61094498 | R12: 0.24723512 | S12: 0.97465484 | T12: -0.00789267 | U12: -0.33564746 | V12: 0.31986212 | W12: 0.17364419 | X12: -0.30061199 | Y12: 0.64790037 | Z12: 0.94670884 | AA12: 0.64992765 | AB12: 1.24349
A13: 44896 | B13: 0.6358192 | C13: 0.079554033 | D13: 1.1920844 | E13: 0.57383293 | F13: -0.032954149 | G13: 1.18062 | H13: 0.54702465 | I13: 0.29370221 | J13: 0.80034709 | K13: 0.43731669 | L13: 0.14945709 | M13: 0.72517629 | N13: 0.81791922 | O13: 0.34295841 | P13: 1.29288 | Q13: 0.61417304 | R13: 0.24950319 | S13: 0.97884289 | T13: 0.15787604 | U13: -0.16987875 | V13: 0.48563083 | W13: 0.35851269 | X13: -0.11592626 | Y13: 0.83295164 | Z13: 1.6120012 | AA13: 1.3129193 | AB13: 1.9110831
A15: =A1 -> data | B15: Alimentos | C15: Transportes | D15: Saúde | E15: Pessoais | F15: Habitação | G15: Residência | H15: Educação | I15: Comunicação | J15: Vestuário
A16: cenario | B16: Base | C16: Base | D16: Base | E16: Base | F16: Base | G16: Base | H16: Base | I16: Base | J16: Base
A17: =A3 -> 44593 | B17: {=_xlfn.IFS(B16="Base",B3:B13,B16="Otimista",C3:C13,B16="Pessimista",D3:D13)} -> 0.85704406 | C17: {=_xlfn.IFS(C16="Base",E3:E13,C16="Otimista",F3:F13,C16="Pessimista",G3:G13)} -> 0.32582383 | D17: {=_xlfn.IFS(D16="Base",H3:H13,D16="Otimista",I3:I13,D16="Pessimista",J3:J13)} -> 0.47732045 | E17: {=_xlfn.IFS(E16="Base",K3:K13,E16="Otimista",L3:L13,E16="Pessimista",M3:M13)} -> 0.35911614 | F17: {=_xlfn.IFS(F16="Base",N3:N13,F16="Otimista",O3:O13,F16="Pessimista",P3:P13)} -> 0.46180284 | G17: {=_xlfn.IFS(G16="Base",Q3:Q13,G16="Otimista",R3:R13,G16="Pessimista",S3:S13)} -> 1.2884769 | H17: {=_xlfn.IFS(H16="Base",T3:T13,H16="Otimista",U3:U13,H16="Pessimista",V3:V13)} -> 2.7734956 | I17: {=_xlfn.IFS(I16="Base",W3:W13,I16="Otimista",X3:X13,I16="Pessimista",Y3:Y13)} -> 0.074640491 | J17: {=_xlfn.IFS(J16="Base",Z3:Z13,J16="Otimista",AA3:AA13,J16="Pessimista",AB3:AB13)} -> 0.82789334
A18: =A4 -> 44621 | B18: 0.70429932 | C18: 0.60046334 | D18: 0.24309911 | E18: 0.2832502 | F18: 0.42403809 | G18: 1.177627 | H18: -0.25131313 | I18: 0.065769139 | J18: 1.188799
A19: =A5 -> 44652 | B19: 0.66198326 | C19: 0.76127518 | D19: 0.57187304 | E19: 0.28761866 | F19: 0.46694077 | G19: 1.0397759 | H19: 0.012615858 | I19: -0.03618657 | J19: 1.2221046
A20: =A6 -> 44682 | B20: 0.63070924 | C20: 0.64166002 | D20: 0.45238886 | E20: 0.33453196 | F20: 0.45412653 | G20: 0.99798846 | H20: 0.041487636 | I20: 0.23674651 | J20: 1.3033515
A21: =A7 -> 44713 | B21: 0.61180436 | C21: 0.34889245 | D21: 0.44542088 | E21: 0.37007456 | F21: 0.4908173 | G21: 0.8626525 | H21: 0.032773598 | I21: 0.088915699 | J21: 1.1773129
A22: =A8 -> 44743 | B22: 0.62017572 | C22: 0.40901244 | D22: 0.061997372 | E22: 0.41132002 | F22: 0.6014254 | G22: 0.75108457 | H22: 0.087187485 | I22: 0.2233752 | J22: 0.55968327
A23: =A9 -> 44774 | B23: 0.69651387 | C23: 0.52605089 | D23: 0.28558614 | E23: 0.47555777 | F23: 0.54149084 | G23: 0.74155465 | H23: -0.85788137 | I23: 0.24593166 | J23: 0.98720671
A24: =A10 -> 44805 | B24: 0.65631039 | C24: 0.43008526 | D24: 0.23802969 | E24: 0.44275617 | F24: 0.53520752 | G24: 0.6562495 | H24: -0.0509797 | I24: 0.23383862 | J24: 0.90108251
A25: =A11 -> 44835 | B25: 0.67050484 | C25: 0.46394161 | D25: 0.39933702 | E25: 0.50476511 | F25: 0.52130575 | G25: 0.66743349 | H25: 0.019471492 | I25: 0.58969787 | J25: 1.6647902
A26: =A12 -> 44866 | B26: 0.54599263 | C26: 0.52850545 | D26: -0.0032973838 | E26: 0.44812996 | F26: 0.54620224 | G26: 0.61094498 | H26: -0.00789267 | I26: 0.17364419 | J26: 0.94670884
A27: =A13 -> 44896 | B27: 0.6358192 | C27: 0.57383293 | D27: 0.54702465 | E27: 0.43731669 | F27: 0.81791922 | G27: 0.61417304 | H27: 0.15787604 | I27: 0.35851269 | J27: 1.6120012
A29: =A15 -> data | B29: Alimentos | C29: Transportes | D29: Saúde | E29: Pessoais | F29: Habitação | G29: Residência | H29: Educação | I29: Comunicação | J29: Vestuário
A30: =A17 -> 44593 | B30: 20.7127 | C30: 21.8902 | D30: 12.3893 | E30: 9.8795 | F30: 16.1423 | G30: 3.8728 | H30: 5.5617 | I30: 5.2143 | J30: 4.337
A31: =A18 -> 44621 | B31: =B30 -> 20.7127 | C31: =C30 -> 21.8902 | D31: =D30 -> 12.3893 | E31: =E30 -> 9.8795 | F31: =F30 -> 16.1423 | G31: =G30 -> 3.8728 | H31: =H30 -> 5.5617 | I31: =I30 -> 5.2143 | J31: =J30 -> 4.337
A32: =A19 -> 44652 | B32: =B31 -> 20.7127 | C32: =C31 -> 21.8902 | D32: =D31 -> 12.3893 | E32: =E31 -> 9.8795 | F32: =F31 -> 16.1423 | G32: =G31 -> 3.8728 | H32: =H31 -> 5.5617 | I32: =I31 -> 5.2143 | J32: =J31 -> 4.337
A33: =A20 -> 44682 | B33: =B32 -> 20.7127 | C33: =C32 -> 21.8902 | D33: =D32 -> 12.3893 | E33: =E32 -> 9.8795 | F33: =F32 -> 16.1423 | G33: =G32 -> 3.8728 | H33: =H32 -> 5.5617 | I33: =I32 -> 5.2143 | J33: =J32 -> 4.337
A34: =A21 -> 44713 | B34: =B33 -> 20.7127 | C34: =C33 -> 21.8902 | D34: =D33 -> 12.3893 | E34: =E33 -> 9.8795 | F34: =F33 -> 16.1423 | G34: =G33 -> 3.8728 | H34: =H33 -> 5.5617 | I34: =I33 -> 5.2143 | J34: =J33 -> 4.337
A35: =A22 -> 44743 | B35: =B34 -> 20.7127 | C35: =C34 -> 21.8902 | D35: =D34 -> 12.3893 | E35: =E34 -> 9.8795 | F35: =F34 -> 16.1423 | G35: =G34 -> 3.8728 | H35: =H34 -> 5.5617 | I35: =I34 -> 5.2143 | J35: =J34 -> 4.337
A36: =A23 -> 44774 | B36: =B35 -> 20.7127 | C36: =C35 -> 21.8902 | D36: =D35 -> 12.3893 | E36: =E35 -> 9.8795 | F36: =F35 -> 16.1423 | G36: =G35 -> 3.8728 | H36: =H35 -> 5.5617 | I36: =I35 -> 5.2143 | J36: =J35 -> 4.337
A37: =A24 -> 44805 | B37: =B36 -> 20.7127 | C37: =C36 -> 21.8902 | D37: =D36 -> 12.3893 | E37: =E36 -> 9.8795 | F37: =F36 -> 16.1423 | G37: =G36 -> 3.8728 | H37: =H36 -> 5.5617 | I37: =I36 -> 5.2143 | J37: =J36 -> 4.337
A38: =A25 -> 44835 | B38: =B37 -> 20.7127 | C38: =C37 -> 21.8902 | D38: =D37 -> 12.3893 | E38: =E37 -> 9.8795 | F38: =F37 -> 16.1423 | G38: =G37 -> 3.8728 | H38: =H37 -> 5.5617 | I38: =I37 -> 5.2143 | J38: =J37 -> 4.337
A39: =A26 -> 44866 | B39: =B38 -> 20.7127 | C39: =C38 -> 21.8902 | D39: =D38 -> 12.3893 | E39: =E38 -> 9.8795 | F39: =F38 -> 16.1423 | G39: =G38 -> 3.8728 | H39: =H38 -> 5.5617 | I39: =I38 -> 5.2143 | J39: =J38 -> 4.337
A40: =A27 -> 44896 | B40: =B39 -> 20.7127 | C40: =C39 -> 21.8902 | D40: =D39 -> 12.3893 | E40: =E39 -> 9.8795 | F40: =F39 -> 16.1423 | G40: =G39 -> 3.8728 | H40: =H39 -> 5.5617 | I40: =I39 -> 5.2143 | J40: =J39 -> 4.337
A42: =A29 -> data | B42: Alimentos | C42: Transportes | D42: Saúde | E42: Pessoais | F42: Habitação | G42: Residência | H42: Educação | I42: Comunicação | J42: Vestuário | K42: IPCA
A43: =A30 -> 44593 | B43: =B30*B17/100 -> 0.17751697 | C43: =C30*C17/100 -> 0.071323489 | D43: =D30*D17/100 -> 0.059136663 | E43: =E30*E17/100 -> 0.035478879 | F43: =F30*F17/100 -> 0.0745456 | G43: =G30*G17/100 -> 0.049900132 | H43: =H30*H17/100 -> 0.1542535 | I43: =I30*I17/100 -> 0.0038919791 | J43: =J30*J17/100 -> 0.035905734 | K43: =SUM(B43:J43) -> 0.66195295
...

Sheet Expectativas de IPCA
A1: data | B1: IPCA | C1: Projeção | D1: Limite Inferior | E1: Meta de Inflação | F1: Limite Superior
A2: 36161 | B2: 1.6455503 | D2: 6 | E2: 8 | F2: 10
A3: 36192 | B3: 2.242513 | D3: 6 | E3: 8 | F3: 10
A4: 36220 | B4: 3.0169231 | D4: 6 | E4: 8 | F4: 10
A5: 36251 | B5: 3.345788 | D5: 6 | E5: 8 | F5: 10
A6: 36281 | B6: 3.1401247 | D6: 6 | E6: 8 | F6: 10
A7: 36312 | B7: 3.3154279 | D7: 6 | E7: 8 | F7: 10
A8: 36342 | B8: 4.5670465 | D8: 6 | E8: 8 | F8: 10
A9: 36373 | B9: 5.6916494 | D9: 6 | E9: 8 | F9: 10
A10: 36404 | B10: 6.2530502 | D10: 6 | E10: 8 | F10: 10
A11: 36434 | B11: 7.4959623 | D11: 6 | E11: 8 | F11: 10
A12: 36465 | B12: 8.647551 | D12: 6 | E12: 8 | F12: 10
A13: 36495 | B13: 8.9399345 | D13: 6 | E13: 8 | F13: 10
... A277: 44531 | B277: 10.061055 | D277: 2.25 | E277: 3.75 | F277: 5.25
A278: 44562 | B278: 10.379436 | C278: =B278 -> 10.379436 | D278: 2 | E278: 3.5 | F278: 5
A279: 44593 | C279: 10.162697 | D279: 2 | E279: 3.5 | F279: 5
A280: 44621 | C280: 9.6829831 | D280: 2 | E280: 3.5 | F280: 5
A281: 44652 | C281: 9.9678095 | D281: 2 | E281: 3.5 | F281: 5
A282: 44682 | C282: 9.6551603 | D282: 2 | E282: 3.5 | F282: 5
A283: 44713 | C283: 9.5842577 | D283: 2 | E283: 3.5 | F283: 5
A284: 44743 | C284: 9.0125093 | D284: 2 | E284: 3.5 | F284: 5
A285: 44774 | C285: 8.5757236 | D285: 2 | E285: 3.5 | F285: 5
A286: 44805 | C286: 7.8282363 | D286: 2 | E286: 3.5 | F286: 5
A287: 44835 | C287: 7.0868182 | D287: 2 | E287: 3.5 | F287: 5
A288: 44866 | C288: 6.5396089 | D288: 2 | E288: 3.5 | F288: 5
A289: 44896 | C289: 6.42484 | D289: 2 | E289: 3.5 | F289: 5

Sheet Crescimento do PIB
A1: data | B1: Carregamento Estatístico | C1: Crescimento Econômico | D1: total
A2: 36526 | B2: 1.2247755 | C2: 3.163174 | D2: 4.3879494
A3: 36892 | B3: 1.8872215 | C3: -0.49732511 | D3: 1.3898964
A4: 37257 | B4: -0.55175641 | C4: 3.6052183 | D4: 3.0534619
A5: 37622 | B5: 1.5393752 | C5: -0.3985462 | D5: 1.140829
A6: 37987 | B6: 1.02526 | C6: 4.7347046 | D6: 5.7599646
A7: 38353 | B7: 1.9076872 | C7: 1.2944481 | D7: 3.2021352
A8: 38718 | B8: 0.90047718 | C8: 3.0615115 | D8: 3.9619887
A9: 39083 | B9: 1.7946863 | C9: 4.2751843 | D9: 6.0698706
A10: 39448 | B10: 2.0721598 | C10: 3.0220357 | D10: 5.0941955
A11: 39814 | B11: -1.5591036 | C11: 1.4332916 | D11: -0.12581199
A12: 40179 | B12: 3.564996 | C12: 3.9632298 | D12: 7.5282258
A13: 40544 | B13: 1.7687958 | C13: 2.2056273 | D13: 3.9744231
... A23: 44197 | B23: 3.7956602 | C23: 0.82376141 | D23: 4.6194216

Sheet Juros Globais - Avançados
A1: data | B1: vertice | C1: valor | D1: variavel
A2: 44561 | B2: 1 | C2: 0.06 | D2: Juro Nominal
A3: 44561 | B3: 3 | C3: 0.06 | D3: Juro Nominal
A4: 44561 | B4: 6 | C4: 0.19 | D4: Juro Nominal
A5: 44561 | B5: 12 | C5: 0.39 | D5: Juro Nominal
A6: 44561 | B6: 24 | C6: 0.73 | D6: Juro Nominal
A7: 44561 | B7: 36 | C7: 0.97 | D7: Juro Nominal
A8: 44561 | B8: 60 | C8: 1.26 | D8: Juro Nominal
A9: 44561 | B9: 84 | C9: 1.44 | D9: Juro Nominal
A10: 44561 | B10: 120 | C10: 1.52 | D10: Juro Nominal
A11: 44561 | B11: 240 | C11: 1.94 | D11: Juro Nominal
A12: 44561 | B12: 360 | C12: 1.9 | D12: Juro Nominal
A13: 44561 | B13: 60 | C13: -1.61 | D13: Juro Real
... A64: 44621 | B64: 360 | C64: 2.2736378 | D64: Inflação Implícita

Sheet Juros Globais - Emergentes
A1: data | B1: 1 | C1: 5 | D1: 10 | E1: economia
A2: 44561 | B2: 5.09 | C2: 7.87 | D2: 9.335 | E2: África do Sul
A3: 44615 | B3: 5.3 | C3: 7.76 | D3: 9.265 | E3: África do Sul
A4: 44621 | B4: 5.43 | C4: 7.95 | D4: 9.675 | E4: África do Sul
A5: 44561 | B5: 11.97 | C5: 10.92 | D5: 11.045 | E5: Brasil
A6: 44615 | B6: 12.53 | C6: 11.06 | D6: 11.17 | E6: Brasil
A7: 44621 | B7: 13.01 | C7: 11.525 | D7: 11.42 | E7: Brasil
A8: 44561 | B8: 4.14 | C8: 5.72 | D8: 5.75 | E8: Chile
A9: 44615 | B9: 7.47 | C9: 5.98 | D9: 5.96 | E9: Chile
A10: 44621 | B10: 7.45 | C10: 5.88 | D10: 5.91 | E10: Chile
A11: 44561 | B11: 3.252 | C11: 7.75 | D11: 8.214 | E11: Colômbia
A12: 44615 | B12: 8.238 | C12: 8.959 | D12: 9.25 | E12: Colômbia
A13: 44621 | B13: 8.32 | C13: 9 | D13: 9.44 | E13: Colômbia
... A19: 44621 | B19: 3.6 | C19: 5.29 | D19: 6.353 | E19: Peru

Sheet Crescimento do PIB - Demanda
A1: data | B1: Consumo Privado | C1: Consumo Público | D1: Investimentos | E1: Exportações Líquidas | F1: pib
A2: 35125 | B2: 1.6531616 | C2: -0.030989032 | D2: -1.4732197 | E2: 0.88043094 | F2: 2.5196866
A3: 35217 | B3: 1.6752442 | C3: -0.13273184 | D3: -1.7206482 | E3: 1.1099754 | F3: 2.1356122
A4: 35309 | B4: 2.146566 | C4: -0.14450991 | D4: -0.84051785 | E4: 0.30845309 | F4: 2.309147
A5: 35400 | B5: 2.1109707 | C5: -0.39917601 | D5: 0.19367613 | E5: -0.56292868 | F5: 2.2088641
A6: 35490 | B6: 3.6777241 | C6: -0.13964502 | D6: 1.1981607 | E6: -1.493052 | F6: 3.1778325
A7: 35582 | B7: 4.29291 | C7: -0.16946065 | D7: 1.8773042 | E7: -2.2691181 | F7: 4.0228433
A8: 35674 | B8: 3.58528 | C8: -0.57185258 | D8: 2.2070631 | E8: -1.9646481 | F8: 3.0255588
A9: 35765 | B9: 1.9345931 | C9: 0.25792162 | D9: 1.5339878 | E9: -0.63917744 | F9: 3.394846
A10: 35855 | B10: 0.70078239 | C10: 0.2479443 | D10: 1.0350907 | E10: -0.047651342 | F10: 2.8134774
A11: 35947 | B11: -0.39957228 | C11: 0.39500483 | D11: 0.83247296 | E11: 0.40303695 | F11: 2.0194318
A12: 36039 | B12: -0.71199311 | C12: 0.96087216 | D12: 0.38701795 | E12: 0.43725241 | F12: 1.6430603
A13: 36130 | B13: -0.45777156 | C13: 0.69083337 | D13: -0.029357989 | E13: 0.32626597 | F13: 0.3380979
... A105: 44531 | B105: 2.3014811 | C105: 0.42972448 | D105: 2.629347 | E105: -1.4078374 | F105: 4.6194216

Sheet Planilha14

Sheet Planilha15
