Workbook

Sheet Variação Mensal
A1: Subitem | B1: Categoria | C1: 202203 | D1: 202202 | E1: 202201 | F1: 202112 | G1: 202111 | H1: 202110 | I1: 202109 | J1: 202108 | K1: 202107 | L1: 202106 | M1: 202105 | N1: 202104 | O1: 202103 | P1: 202102 | Q1: 202101 | R1: 202012 | S1: 202011 | T1: 202010 | U1: 202009 | V1: 202008 | W1: 202007 | X1: 202006 | Y1: 202005 | Z1: 202004 | AA1: 202003 | AB1: 202002 | AC1: 202001 | AD1: 201912 | AE1: 201911 | AF1: 201910 | AG1: 201909 | AH1: 201908 | AI1: 201907 | AJ1: 201906 | AK1: 201905 | AL1: 201904 | AM1: 201903 | AN1: 201902 | AO1: 201901 | AP1: 201812 | AQ1: 201811 | AR1: 201810 | AS1: 201809 | AT1: 201808 | AU1: 201807 | AV1: 201806 | AW1: 201805 | AX1: 201804 | AY1: 201803 | AZ1: 201802 | BA1: 201801 | BB1: 201712 | BC1: 201711 | BD1: 201710 | BE1: 201709 | BF1: 201708 | BG1: 201707 | BH1: 201706 | BI1: 201705 | BJ1: 201704 | BK1: 201703 | BL1: 201702 | BM1: 201701 | BN1: 201612 | BO1: 201611 | BP1: 201610 | BQ1: 201609 | BR1: 201608 | BS1: 201607 | BT1: 201606 | BU1: 201605 | BV1: 201604 | BW1: 201603 | BX1: 201602 | BY1: 201601 | BZ1: 201512 | CA1: 201511 | CB1: 201510 | CC1: 201509 | CD1: 201508 | CE1: 201507 | CF1: 201506 | CG1: 201505 | CH1: 201504 | CI1: 201503 | CJ1: 201502 | CK1: 201501 | CL1: 201412 | CM1: 201411 | CN1: 201410 | CO1: 201409 | CP1: 201408 | CQ1: 201407 | CR1: 201406 | CS1: 201405 | CT1: 201404 | CU1: 201403 | CV1: 201402 | CW1: 201401 | CX1: 201312 | CY1: 201311 | CZ1: 201310 | DA1: 201309 | DB1: 201308 | DC1: 201307 | DD1: 201306 | DE1: 201305 | DF1: 201304 | DG1: 201303 | DH1: 201302 | DI1: 201301 | DJ1: 201212 | DK1: 201211 | DL1: 201210 | DM1: 201209 | DN1: 201208 | DO1: 201207 | DP1: 201206 | DQ1: 201205 | DR1: 201204 | DS1: 201203 | DT1: 201202 | DU1: 201201 | DV1: 201112 | DW1: 201111 | DX1: 201110 | DY1: 201109 | DZ1: 201108 | EA1: 201107 | EB1: 201106 | EC1: 201105 | ED1: 201104 | EE1: 201103 | EF1: 201102 | EG1: 201101 | EH1: 201012 | EI1: 201011 | EJ1: 201010 | EK1: 201009 | EL1: 201008 | EM1: 201007 | EN1: 201006 | EO1: 201005 | EP1: 201004 | EQ1: 201003 | ER1: 201002 | ES1: 201001 | ET1: 200912 | EU1: 200911 | EV1: 200910 | EW1: 200909 | EX1: 200908 | EY1: 200907 | EZ1: 200906 | FA1: 200905 | FB1: 200904 | FC1: 200903 | FD1: 200902 | FE1: 200901 | FF1: 200812 | FG1: 200811 | FH1: 200810 | FI1: 200809 | FJ1: 200808 | FK1: 200807 | FL1: 200806 | FM1: 200805 | FN1: 200804 | FO1: 200803 | FP1: 200802 | FQ1: 200801 | FR1: 200712 | FS1: 200711 | FT1: 200710 | FU1: 200709 | FV1: 200708 | FW1: 200707 | FX1: 200706 | FY1: 200705 | FZ1: 200704 | GA1: 200703 | GB1: 200702 | GC1: 200701 | GD1: 200612 | GE1: 200611 | GF1: 200610 | GG1: 200609 | GH1: 200608 | GI1: 200607
A2: Índice Geral | B2: Índice Geral | C2: 1.62 | D2: 1.01 | E2: 0.54 | F2: 0.73 | G2: 0.95 | H2: 1.25 | I2: 1.16 | J2: 0.87 | K2: 0.96 | L2: 0.53 | M2: 0.83 | N2: 0.31 | O2: 0.93 | P2: 0.86 | Q2: 0.25 | R2: 1.35 | S2: 0.89 | T2: 0.86 | U2: 0.64 | V2: 0.24 | W2: 0.36 | X2: 0.26 | Y2: -0.38 | Z2: -0.31 | AA2: 0.07 | AB2: 0.25 | AC2: 0.21 | AD2: 1.15 | AE2: 0.51 | AF2: 0.1 | AG2: -0.04 | AH2: 0.11 | AI2: 0.19 | AJ2: 0.01 | AK2: 0.13 | AL2: 0.57 | AM2: 0.75 | AN2: 0.43 | AO2: 0.32 | AP2: 0.15 | AQ2: -0.21 | AR2: 0.45 | AS2: 0.48 | AT2: -0.09 | AU2: 0.33 | AV2: 1.26 | AW2: 0.4 | AX2: 0.22 | AY2: 0.09 | AZ2: 0.32 | BA2: 0.29 | BB2: 0.44 | BC2: 0.28 | BD2: 0.42 | BE2: 0.16 | BF2: 0.19 | BG2: 0.24 | BH2: -0.23 | BI2: 0.31 | BJ2: 0.14 | BK2: 0.25 | BL2: 0.33 | BM2: 0.38 | BN2: 0.3 | BO2: 0.18 | BP2: 0.26 | BQ2: 0.08 | BR2: 0.44 | BS2: 0.52 | BT2: 0.35 | BU2: 0.78 | BV2: 0.61 | BW2: 0.43 | BX2: 0.9 | BY2: 1.27 | BZ2: 0.96 | CA2: 1.01 | CB2: 0.82 | CC2: 0.54 | CD2: 0.22 | CE2: 0.62 | CF2: 0.79 | CG2: 0.74 | CH2: 0.71 | CI2: 1.32 | CJ2: 1.22 | CK2: 1.24 | CL2: 0.78 | CM2: 0.51 | CN2: 0.42 | CO2: 0.57 | CP2: 0.25 | CQ2: 0.01 | CR2: 0.4 | CS2: 0.46 | CT2: 0.67 | CU2: 0.92 | CV2: 0.69 | CW2: 0.55 | CX2: 0.92 | CY2: 0.54 | CZ2: 0.57 | DA2: 0.35 | DB2: 0.24 | DC2: 0.03 | DD2: 0.26 | DE2: 0.37 | DF2: 0.55 | DG2: 0.47 | DH2: 0.6 | DI2: 0.86 | DJ2: 0.79 | DK2: 0.6 | DL2: 0.59 | DM2: 0.57 | DN2: 0.41 | DO2: 0.43 | DP2: 0.08 | DQ2: 0.36 | DR2: 0.64 | DS2: 0.21 | DT2: 0.45 | DU2: 0.56 | DV2: 0.5 | DW2: 0.52 | DX2: 0.43 | DY2: 0.53 | DZ2: 0.37 | EA2: 0.16 | EB2: 0.15 | EC2: 0.47 | ED2: 0.77 | EE2: 0.79 | EF2: 0.8 | EG2: 0.83 | EH2: 0.63 | EI2: 0.83 | EJ2: 0.75 | EK2: 0.45 | EL2: 0.04 | EM2: 0.01 | EN2: 0 | EO2: 0.43 | EP2: 0.57 | EQ2: 0.52 | ER2: 0.78 | ES2: 0.75 | ET2: 0.37 | EU2: 0.41 | EV2: 0.28 | EW2: 0.24 | EX2: 0.15 | EY2: 0.24 | EZ2: 0.36 | FA2: 0.47 | FB2: 0.48 | FC2: 0.2 | FD2: 0.55 | FE2: 0.48 | FF2: 0.28 | FG2: 0.36 | FH2: 0.45 | FI2: 0.26 | FJ2: 0.28 | FK2: 0.53 | FL2: 0.74 | FM2: 0.79 | FN2: 0.55 | FO2: 0.48 | FP2: 0.49 | FQ2: 0.54 | FR2: 0.74 | FS2: 0.38 | FT2: 0.3 | FU2: 0.18 | FV2: 0.47 | FW2: 0.24 | FX2: 0.28 | FY2: 0.28 | FZ2: 0.25 | GA2: 0.37 | GB2: 0.44 | GC2: 0.44 | GD2: 0.48 | GE2: 0.31 | GF2: 0.33 | GG2: 0.21 | GH2: 0.05 | GI2: 0.19
A3: Arroz | B3: Alimentos | C3: 2.69 | D3: 0.14 | E3: -2.66 | F3: -1.77 | G3: -3.58 | H3: -1.42 | I3: -0.97 | J3: -2.09 | K3: -2.35 | L3: -1.06 | M3: -1.14 | N3: -0.5 | O3: -2.13 | P3: -1.52 | Q3: 0.24 | R3: 3.84 | S3: 6.28 | T3: 13.36 | U3: 17.98 | V3: 3.08 | W3: 2.2 | X3: 2.74 | Y3: 2.01 | Z3: 3.88 | AA3: 1.6 | AB3: 1 | AC3: 1.31 | AD3: 0.17 | AE3: 0.69 | AF3: 0.05 | AG3: 0.63 | AH3: 0.67 | AI3: 0.48 | AJ3: 0.5 | AK3: -0.4 | AL3: -0.16 | AM3: -0.41 | AN3: -1.23 | AO3: 0.19 | AP3: -1.19 | AQ3: 0.35 | AR3: 1.09 | AS3: 2.16 | AT3: 2.51 | AU3: 2.02 | AV3: 3.02 | AW3: -1.08 | AX3: -1.11 | AY3: -1.2 | AZ3: -1.02 | BA3: -0.23 | BB3: -0.03 | BC3: -0.95 | BD3: -1.14 | BE3: -0.39 | BF3: -0.95 | BG3: -1.52 | BH3: -0.92 | BI3: -1.98 | BJ3: -1.69 | BK3: -1.13 | BL3: -0.6 | BM3: -0.12 | BN3: 0.21 | BO3: -0.15 | BP3: 0.39 | BQ3: 1.13 | BR3: 2.92 | BS3: 4.68 | BT3: 2 | BU3: 0.54 | BV3: 0.34 | BW3: 0.96 | BX3: 0.8 | BY3: 1.37 | BZ3: 1.64 | CA3: 3.13 | CB3: 3.77 | CC3: 0.37 | CD3: -0.26 | CE3: -0.29 | CF3: 0.06 | CG3: 0.37 | CH3: -0.82 | CI3: 0.44 | CJ3: 0.38 | CK3: 0.57 | CL3: 1.81 | CM3: -0.06 | CN3: 1.15 | CO3: 0.68 | CP3: -1.07 | CQ3: 0.45 | CR3: 1.23 | CS3: 1.57 | CT3: 0.29 | CU3: 0.22 | CV3: 0.94 | CW3: 1.12 | CX3: 0.86 | CY3: -1.04 | CZ3: -0.16 | DA3: 0.26 | DB3: -0.12 | DC3: -0.01 | DD3: 0.67 | DE3: -1.23 | DF3: -1.87 | DG3: -1.68 | DH3: -0.57 | DI3: -0.05 | DJ3: 1.19 | DK3: 4.05 | DL3: 9.88 | DM3: 8.21 | DN3: 1.76 | DO3: 0.67 | DP3: 1.01 | DQ3: 2.11 | DR3: 0.44 | DS3: 0.5 | DT3: 1.02 | DU3: 1.32 | DV3: 0.43 | DW3: 0.48 | DX3: 0.25 | DY3: 1.97 | DZ3: 1.82 | EA3: -1.19 | EB3: -1.8 | EC3: -1.68 | ED3: -2.13 | EE3: -0.9 | EF3: -1.58 | EG3: -0.76 | EH3: 0.21 | EI3: -1.22 | EJ3: -1.14 | EK3: 0.32 | EL3: -1.01 | EM3: -1.05 | EN3: -0.68 | EO3: -0.15 | EP3: -1.27 | EQ3: -0.47 | ER3: 4.45 | ES3: 3.26 | ET3: -0.87 | EU3: -0.25 | EV3: -0.1 | EW3: -0.76 | EX3: 0.28 | EY3: -0.29 | EZ3: -3.15 | FA3: -2.3 | FB3: -2.57 | FC3: -1.8 | FD3: -0.82 | FE3: -1.29 | FF3: -1.77 | FG3: 0.14 | FH3: 1.46 | FI3: -0.81 | FJ3: -1.59 | FK3: -0.51 | FL3: 9.9 | FM3: 19.75 | FN3: 1.96 | FO3: 0.72 | FP3: 1.62 | FQ3: 0.62 | FR3: -1.01 | FS3: 0.33 | FT3: 2.09 | FU3: 3.54 | FV3: 1.58 | FW3: -0.48 | FX3: 0.16 | FY3: -0.7 | FZ3: -1.13 | GA3: -2.99 | GB3: -2.35 | GC3: -0.77 | GD3: 4.44 | GE3: 5.32 | GF3: 0.72 | GG3: -0.16 | GH3: 2.03 | GI3: 4.33
A4: Feijão-Mulatinho | B4: Alimentos | C4: -3.61 | D4: 9.35 | E4: -2.97 | F4: -0.09 | G4: -0.47 | H4: -1.89 | I4: -3.04 | J4: -0.51 | K4: 4.99 | L4: 1.27 | M4: 1.08 | N4: 3.74 | O4: -0.32 | P4: 1.25 | Q4: 1.38 | R4: -1.03 | S4: 0.25 | T4: 3.1 | U4: -3.24 | V4: -1.39 | W4: 0.76 | X4: 7.1 | Y4: 1.44 | Z4: 15.34 | AA4: 5.86 | AB4: -3.73 | AC4: 4.5 | AD4: 1.53 | AE4: -8.15 | AF4: -4.3 | AG4: -8.66 | AH4: 0.37 | AI4: -0.45 | AJ4: -6.1 | AK4: -2.91 | AL4: -7.81 | AM4: 17.05 | AN4: 22.3 | AO4: 14.93 | AP4: 2.54 | AQ4: 0.67 | AR4: 0.92 | AS4: -0.49 | AT4: -0.94 | AU4: 1.22 | AV4: -1.54 | AW4: 1.11 | AX4: -0.39 | AY4: 1.05 | AZ4: 0.31 | BA4: -1.92 | BB4: -4.35 | BC4: -0.2 | BD4: -18.41 | BE4: -19.64 | BF4: -11.31 | BG4: -0.56 | BH4: -0.08 | BI4: -0.26 | BJ4: 1.09 | BK4: -4.5 | BL4: 4.35 | BM4: -0.07 | BN4: -4.39 | BO4: -0.81 | BP4: -4.85 | BQ4: -1.45 | BR4: 3.4 | BS4: 18.89 | BT4: 34.15 | BU4: 9.85 | BV4: 1.42 | BW4: 2.41 | BX4: 9.76 | BY4: 9.75 | BZ4: 5.25 | CA4: 2.89 | CB4: -2.99 | CC4: -3.43 | CD4: -3.28 | CE4: 8.88 | CF4: 1.33 | CG4: -0.94 | CH4: 6.55 | CI4: 2.06 | CJ4: 10.47 | CK4: 3.26 | CL4: 7.49 | CM4: -2.67 | CN4: -3.75 | CO4: -4.92 | CP4: -11.68 | CQ4: -1.95 | CR4: -1.11 | CS4: 1.59 | CT4: 2.98 | CU4: -2.9 | CV4: -0.16 | CW4: -6.1 | CX4: -0.92 | CY4: -1.98 | CZ4: -7.23 | DA4: -19.73 | DB4: -10.87 | DC4: 0.6 | DD4: -4.27 | DE4: 16.58 | DF4: 7.76 | DG4: 0.38 | DH4: 1.36 | DI4: 8.33 | DJ4: -2.12 | DK4: -0.26 | DL4: -2.2 | DM4: -6.9 | DN4: -4.61 | DO4: 4.38 | DP4: 7.9 | DQ4: 17.92 | DR4: 13.09 | DS4: 1.28 | DT4: 2.82 | DU4: 15.98 | DV4: 3.17 | DW4: 0.05 | DX4: 1.14 | DY4: -0.77 | DZ4: -1.88 | EA4: 4.83 | EB4: -1.68 | EC4: -1.1 | ED4: 4.54 | EE4: 0.59 | EF4: 0 | EG4: -4.78 | EH4: -5.83 | EI4: -1.21 | EJ4: 12.1 | EK4: 3.19 | EL4: -5.65 | EM4: 4.71 | EN4: 1.61 | EO4: 8.28 | EP4: 10.43 | EQ4: 6.41 | ER4: 0.8 | ES4: -1.8 | ET4: -4.09 | EU4: 1.24 | EV4: -3.26 | EW4: -6.44 | EX4: -5.21 | EY4: -6.3 | EZ4: -2.9 | FA4: -0.62 | FB4: -0.51 | FC4: -6.78 | FD4: 2.1 | FE4: -3.84 | FF4: -11.71 | FG4: -8.05 | FH4: 1.52 | FI4: -2.83 | FJ4: -6.46 | FK4: -2.12 | FL4: 3.78 | FM4: -2.83 | FN4: -5.13 | FO4: -1.5 | FP4: 8.17 | FQ4: 17.17 | FR4: 33.14 | FS4: 30.8 | FT4: 15.31 | FU4: 3.9 | FV4: 1.87 | FW4: 3.03 | FX4: 0.18 | FY4: -0.19 | FZ4: 5.61 | GA4: 2.27 | GB4: -0.5 | GC4: 0.29 | GD4: 1.35 | GE4: 3.81 | GF4: 1.54 | GG4: -10.22 | GH4: -4.66 | GI4: -8.61
A5: Feijão-Preto | B5: Alimentos | C5: 2.6 | D5: 3.05 | E5: -1.73 | F5: -0.51 | G5: -3.7 | H5: -1.34 | I5: -1.85 | J5: -1.66 | K5: -1.87 | L5: -0.03 | M5: -0.73 | N5: 3.85 | O5: 0.86 | P5: 0.77 | Q5: 3.25 | R5: 3.29 | S5: 2.2 | T5: 2.41 | U5: 4.31 | V5: -0.45 | W5: 1.25 | X5: 6.75 | Y5: 7.44 | Z5: 10.41 | AA5: 1.24 | AB5: 2.52 | AC5: -2.68 | AD5: 4.53 | AE5: -1.71 | AF5: -2.78 | AG5: -1.9 | AH5: -0.94 | AI5: -3.48 | AJ5: -8.29 | AK5: -8.76 | AL5: -3.86 | AM5: 12.55 | AN5: 22.62 | AO5: 3.59 | AP5: 1.02 | AQ5: -0.96 | AR5: 3.11 | AS5: 0.83 | AT5: 0.06 | AU5: -1.02 | AV5: 1.46 | AW5: -1.55 | AX5: -2.48 | AY5: -2.72 | AZ5: -1.05 | BA5: -0.28 | BB5: -0.58 | BC5: -3.1 | BD5: -3.52 | BE5: -2.69 | BF5: -6.36 | BG5: 5.44 | BH5: 2.01 | BI5: -3.66 | BJ5: -8.29 | BK5: -9.11 | BL5: -9.22 | BM5: -3.75 | BN5: -0.25 | BO5: -0.77 | BP5: -1.56 | BQ5: -3.77 | BR5: 2.82 | BS5: 41.59 | BT5: 9.8 | BU5: -0.37 | BV5: 1.2 | BW5: 5.26 | BX5: 8.43 | BY5: 3.22 | BZ5: 0.99 | CA5: -0.34 | CB5: 1.67 | CC5: 0.05 | CD5: -1.8 | CE5: -4.04 | CF5: -1 | CG5: -2.14 | CH5: -2.26 | CI5: 0.41 | CJ5: 3.84 | CK5: 2.76 | CL5: 3.84 | CM5: -5.34 | CN5: 0.36 | CO5: 0.92 | CP5: -3.16 | CQ5: -4.22 | CR5: -3.67 | CS5: 3.79 | CT5: 4.08 | CU5: -0.29 | CV5: -2.07 | CW5: -1.08 | CX5: -0.43 | CY5: -1.04 | CZ5: 0.56 | DA5: 0.2 | DB5: 3.74 | DC5: 5.58 | DD5: 4.19 | DE5: 2.78 | DF5: -0.37 | DG5: 1.83 | DH5: 2.42 | DI5: 0.41 | DJ5: 2.08 | DK5: -1.37 | DL5: 1.56 | DM5: 2.17 | DN5: -0.22 | DO5: 6.12 | DP5: 3.48 | DQ5: 3.04 | DR5: 1.03 | DS5: 0.57 | DT5: 14.14 | DU5: 5.42 | DV5: 0.55 | DW5: 0.34 | DX5: 1.2 | DY5: -0.13 | DZ5: 0.37 | EA5: -1.43 | EB5: -1.56 | EC5: -0.83 | ED5: 0.31 | EE5: -3.03 | EF5: -3.15 | EG5: -4.14 | EH5: -1.93 | EI5: 2.11 | EJ5: 8.44 | EK5: 1.57 | EL5: -0.07 | EM5: 0.39 | EN5: 0.11 | EO5: 8.01 | EP5: 4.72 | EQ5: 0.45 | ER5: 3.15 | ES5: 0.19 | ET5: -2.83 | EU5: -2.49 | EV5: -1.18 | EW5: -4.84 | EX5: -2.17 | EY5: -1.37 | EZ5: -8.23 | FA5: -10.75 | FB5: -12.32 | FC5: -11.87 | FD5: 1.54 | FE5: 0.84 | FF5: -6.95 | FG5: 3.49 | FH5: 7.74 | FI5: -2.12 | FJ5: -1.96 | FK5: 5.39 | FL5: 7.54 | FM5: 1.17 | FN5: -0.73 | FO5: 5.54 | FP5: 13.66 | FQ5: 21.76 | FR5: 12.47 | FS5: 10.87 | FT5: 9.98 | FU5: 6.04 | FV5: 3.7 | FW5: 4.02 | FX5: 1.01 | FY5: -1.86 | FZ5: -1.08 | GA5: -3.64 | GB5: -3.97 | GC5: -2.33 | GD5: -1.07 | GE5: -1.14 | GF5: -1.99 | GG5: -5.54 | GH5: -4.26 | GI5: -2.99
A6: Feijão-Macáçar (Fradinho) | B6: Alimentos | C6: 1.24 | D6: 4.16 | E6: -1.84 | F6: 0.16 | G6: -0.3 | H6: -1.7 | I6: -0.66 | J6: 0.7 | K6: -0.26 | L6: -3.53 | M6: 7.59 | N6: 1.34 | O6: 4.84 | P6: -0.38 | Q6: 2.8 | R6: 5.07 | S6: 0.93 | T6: 0.76 | U6: 15.73 | V6: 2.24 | W6: 3.77 | X6: 2.88 | Y6: 2.62 | Z6: 5.55 | AA6: 6.52 | AB6: 2.39 | AC6: 5.39 | AD6: 0 | AE6: 0 | AF6: 0 | AG6: 0 | AH6: 0 | AI6: 0 | AJ6: 0 | AK6: 0 | AL6: 0 | AM6: 0 | AN6: 0 | AO6: 0 | AP6: 0 | AQ6: 0 | AR6: 0 | AS6: 0 | AT6: 0 | AU6: 0 | AV6: 0 | AW6: 0 | AX6: 0 | AY6: 0 | AZ6: 0 | BA6: 0 | BB6: 0 | BC6: 0 | BD6: 0 | BE6: 0 | BF6: 0 | BG6: 0 | BH6: 0 | BI6: 0 | BJ6: 0 | BK6: 0 | BL6: 0 | BM6: 0 | BN6: 0 | BO6: 0 | BP6: 0 | BQ6: 0 | BR6: 0 | BS6: 0 | BT6: 0 | BU6: 0 | BV6: 0 | BW6: 0 | BX6: 0 | BY6: 0 | BZ6: 0 | CA6: 0 | CB6: 0 | CC6: 0 | CD6: 0 | CE6: 0 | CF6: 0 | CG6: 0 | CH6: 0 | CI6: 0 | CJ6: 0 | CK6: 0 | CL6: 0 | CM6: 0 | CN6: 0 | CO6: 0 | CP6: 0 | CQ6: 0 | CR6: 0 | CS6: 0 | CT6: 0 | CU6: 0 | CV6: 0 | CW6: 0 | CX6: 0 | CY6: 0 | CZ6: 0 | DA6: 0 | DB6: 0 | DC6: 0 | DD6: 0 | DE6: 0 | DF6: 0 | DG6: 0 | DH6: 0 | DI6: 0 | DJ6: 0 | DK6: 0 | DL6: 0 | DM6: 0 | DN6: 0 | DO6: 0 | DP6: 0 | DQ6: 0 | DR6: 0 | DS6: 0 | DT6: 0 | DU6: 0 | DV6: 0 | DW6: 0 | DX6: 0 | DY6: 0 | DZ6: 0 | EA6: 0 | EB6: 0 | EC6: 0 | ED6: 0 | EE6: 0 | EF6: 0 | EG6: 0 | EH6: 0 | EI6: 0 | EJ6: 0 | EK6: 0 | EL6: 0 | EM6: 0 | EN6: 0 | EO6: 0 | EP6: 0 | EQ6: 0 | ER6: 0 | ES6: 0 | ET6: 0 | EU6: 0 | EV6: 0 | EW6: 0 | EX6: 0 | EY6: 0 | EZ6: 0 | FA6: 0 | FB6: 0 | FC6: 0 | FD6: 0 | FE6: 0 | FF6: 0 | FG6: 0 | FH6: 0 | FI6: 0 | FJ6: 0 | FK6: 0 | FL6: 0 | FM6: 0 | FN6: 0 | FO6: 0 | FP6: 0 | FQ6: 0 | FR6: 0 | FS6: 0 | FT6: 0 | FU6: 0 | FV6: 0 | FW6: 0 | FX6: 0 | FY6: 0 | FZ6: 0 | GA6: 0 | GB6: 0 | GC6: 0 | GD6: 0 | GE6: 0 | GF6: 0 | GG6: 0 | GH6: 0 | GI6: 0
A7: Feijão-Carioca (Rajado) | B7: Alimentos | C7: 6.43 | D7: 4.77 | E7: 0.24 | F7: -2.65 | G7: -2.16 | H7: -1.47 | I7: -0.31 | J7: -0.84 | K7: -0.9 | L7: 0.78 | M7: -1.38 | N7: 0.64 | O7: 0.18 | P7: -1.52 | Q7: 1.27 | R7: 2.86 | S7: 0.81 | T7: 0.38 | U7: -0.41 | V7: -5.85 | W7: -5.95 | X7: 4.96 | Y7: 8.66 | Z7: 17.29 | AA7: -1.29 | AB7: -3.44 | AC7: -0.7 | AD7: 23.35 | AE7: 6.66 | AF7: 0.24 | AG7: -2.9 | AH7: -3.21 | AI7: -8.86 | AJ7: -14.8 | AK7: -13.04 | AL7: -9.09 | AM7: 12.93 | AN7: 51.58 | AO7: 19.76 | AP7: 12.98 | AQ7: -0.9 | AR7: -1.2 | AS7: 1.42 | AT7: -2.14 | AU7: -2.67 | AV7: 2.63 | AW7: 3.2 | AX7: 1.31 | AY7: -2.79 | AZ7: -2.98 | BA7: -3.32 | BB7: -6.73 | BC7: -8.4 | BD7: -3.29 | BE7: -9.43 | BF7: -14.86 | BG7: -5.39 | BH7: 25.86 | BI7: 3.29 | BJ7: -1.64 | BK7: -5.59 | BL7: -14.22 | BM7: -13.58 | BN7: -13.77 | BO7: -17.52 | BP7: -8.79 | BQ7: -4.61 | BR7: -5.6 | BS7: 32.42 | BT7: 41.78 | BU7: 7.61 | BV7: 4 | BW7: 4.1 | BX7: 6.82 | BY7: 7.26 | BZ7: 7.02 | CA7: 3.23 | CB7: 0.14 | CC7: -0.57 | CD7: -3.37 | CE7: 2.03 | CF7: -2.18 | CG7: -4.17 | CH7: -1.61 | CI7: 3.4 | CJ7: 6.87 | CK7: 17.95 | CL7: 12.62 | CM7: 0.14 | CN7: 0.3 | CO7: -5.61 | CP7: -3.77 | CQ7: -6.42 | CR7: -6.78 | CS7: 0.03 | CT7: 4.71 | CU7: 11.81 | CV7: -4.45 | CW7: -3.99 | CX7: -6.62 | CY7: -7.96 | CZ7: -9.3 | DA7: -13.95 | DB7: -8.02 | DC7: -4.96 | DD7: -2.19 | DE7: 7.23 | DF7: 9.44 | DG7: 9.08 | DH7: 6.99 | DI7: 5.27 | DJ7: 3.55 | DK7: -2.07 | DL7: 1.54 | DM7: -1.62 | DN7: -9.27 | DO7: -6.78 | DP7: -3.07 | DQ7: 10.02 | DR7: 12.66 | DS7: 0.93 | DT7: 10.01 | DU7: 15.06 | DV7: 8.84 | DW7: -0.88 | DX7: -1.88 | DY7: 6.14 | DZ7: 0.58 | EA7: 0.5 | EB7: -0.74 | EC7: 1.59 | ED7: 9.79 | EE7: 1.71 | EF7: -10.5 | EG7: -15.02 | EH7: -16.45 | EI7: -6.64 | EJ7: 31.42 | EK7: 0.39 | EL7: -11.23 | EM7: -1.47 | EN7: 2.47 | EO7: 12.96 | EP7: 43.13 | EQ7: 10.46 | ER7: -1.82 | ES7: 1.19 | ET7: -1.42 | EU7: -4.17 | EV7: -4.72 | EW7: -6.17 | EX7: -5.24 | EY7: 6.46 | EZ7: 0.76 | FA7: -6 | FB7: -8.72 | FC7: -12.91 | FD7: -3.35 | FE7: 3.47 | FF7: -19.02 | FG7: -14.6 | FH7: 4.86 | FI7: -1.64 | FJ7: -5.9 | FK7: 6.59 | FL7: 15.55 | FM7: -11.26 | FN7: -10.99 | FO7: -9.24 | FP7: 6.29 | FQ7: 11.93 | FR7: 38.61 | FS7: 23.13 | FT7: 15.85 | FU7: 4.09 | FV7: 5.11 | FW7: 4.52 | FX7: 15.73 | FY7: 1.75 | FZ7: -2.09 | GA7: -2.54 | GB7: -3.12 | GC7: -0.75 | GD7: -0.81 | GE7: 3.03 | GF7: 5.26 | GG7: -2.11 | GH7: -8.05 | GI7: -9.71
A8: Milho (Em Grão) | B8: Alimentos | C8: 2.04 | D8: 1.11 | E8: 2.18 | F8: 0.34 | G8: 1.49 | H8: 2.89 | I8: 6.08 | J8: 1.86 | K8: -1.17 | L8: -0.43 | M8: 1.04 | N8: 3.95 | O8: 0.32 | P8: 0.22 | Q8: 0.82 | R8: 2.69 | S8: -0.96 | T8: 1.34 | U8: 3.35 | V8: -0.06 | W8: 0.74 | X8: 0 | Y8: 0.74 | Z8: 1.01 | AA8: 0.88 | AB8: 2.94 | AC8: 0.2 | AD8: 0 | AE8: 0 | AF8: 0 | AG8: 0 | AH8: 0 | AI8: 0 | AJ8: 0 | AK8: 0 | AL8: 0 | AM8: 0 | AN8: 0 | AO8: 0 | AP8: 0 | AQ8: 0 | AR8: 0 | AS8: 0 | AT8: 0 | AU8: 0 | AV8: 0 | AW8: 0 | AX8: 0 | AY8: 0 | AZ8: 0 | BA8: 0 | BB8: 0 | BC8: 0 | BD8: 0 | BE8: 0 | BF8: 0 | BG8: 0 | BH8: 0 | BI8: 0 | BJ8: 0 | BK8: 0 | BL8: 0 | BM8: 0 | BN8: 0 | BO8: 0 | BP8: 0 | BQ8: 0 | BR8: 0 | BS8: 0 | BT8: 0 | BU8: 0 | BV8: 0 | BW8: 0 | BX8: 0 | BY8: 0 | BZ8: 0 | CA8: 0 | CB8: 0 | CC8: 0 | CD8: 0 | CE8: 0 | CF8: 0 | CG8: 0 | CH8: 0 | CI8: 0 | CJ8: 0 | CK8: 0 | CL8: 0 | CM8: 0 | CN8: 0 | CO8: 0 | CP8: 0 | CQ8: 0 | CR8: 0 | CS8: 0 | CT8: 0 | CU8: 0 | CV8: 0 | CW8: 0 | CX8: 0 | CY8: 0 | CZ8: 0 | DA8: 0 | DB8: 0 | DC8: 0 | DD8: 0 | DE8: 0 | DF8: 0 | DG8: 0 | DH8: 0 | DI8: 0 | DJ8: 0 | DK8: 0 | DL8: 0 | DM8: 0 | DN8: 0 | DO8: 0 | DP8: 0 | DQ8: 0 | DR8: 0 | DS8: 0 | DT8: 0 | DU8: 0 | DV8: 0 | DW8: 0 | DX8: 0 | DY8: 0 | DZ8: 0 | EA8: 0 | EB8: 0 | EC8: 0 | ED8: 0 | EE8: 0 | EF8: 0 | EG8: 0 | EH8: 0 | EI8: 0 | EJ8: 0 | EK8: 0 | EL8: 0 | EM8: 0 | EN8: 0 | EO8: 0 | EP8: 0 | EQ8: 0 | ER8: 0 | ES8: 0 | ET8: 0 | EU8: 0 | EV8: 0 | EW8: 0 | EX8: 0 | EY8: 0 | EZ8: 0 | FA8: 0 | FB8: 0 | FC8: 0 | FD8: 0 | FE8: 0 | FF8: 0 | FG8: 0 | FH8: 0 | FI8: 0 | FJ8: 0 | FK8: 0 | FL8: 0 | FM8: 0 | FN8: 0 | FO8: 0 | FP8: 0 | FQ8: 0 | FR8: 0 | FS8: 0 | FT8: 0 | FU8: 0 | FV8: 0 | FW8: 0 | FX8: 0 | FY8: 0 | FZ8: 0 | GA8: 0 | GB8: 0 | GC8: 0 | GD8: 0 | GE8: 0 | GF8: 0 | GG8: 0 | GH8: 0 | GI8: 0
A9: Feijão-Macassar (Fradinho) | B9: Alimentos | C9: 0 | D9: 0 | E9: 0 | F9: 0 | G9: 0 | H9: 0 | I9: 0 | J9: 0 | K9: 0 | L9: 0 | M9: 0 | N9: 0 | O9: 0 | P9: 0 | Q9: 0 | R9: 0 | S9: 0 | T9: 0 | U9: 0 | V9: 0 | W9: 0 | X9: 0 | Y9: 0 | Z9: 0 | AA9: 0 | AB9: 0 | AC9: 0 | AD9: 6.54 | AE9: 4.53 | AF9: 0.65 | AG9: -1.45 | AH9: -0.02 | AI9: 1.39 | AJ9: -2.05 | AK9: -5.96 | AL9: 0.71 | AM9: 9.45 | AN9: 14.47 | AO9: 1.54 | AP9: -1.95 | AQ9: 1.83 | AR9: -1.62 | AS9: -2.05 | AT9: -0.35 | AU9: -0.65 | AV9: 1.21 | AW9: -2.41 | AX9: -2.26 | AY9: -3.98 | AZ9: -1.83 | BA9: -3.94 | BB9: 0.01 | BC9: -2.81 | BD9: -2.79 | BE9: -6.01 | BF9: -5.26 | BG9: -7.11 | BH9: -6.6 | BI9: -4.45 | BJ9: -0.82 | BK9: 1.33 | BL9: -3.15 | BM9: -0.47 | BN9: -0.16 | BO9: -3.24 | BP9: 4.02 | BQ9: -0.19 | BR9: 11.27 | BS9: 14.72 | BT9: 9.32 | BU9: -0.91 | BV9: 0.06 | BW9: 1.2 | BX9: 8.72 | BY9: 3.71 | BZ9: 7.24 | CA9: 2.15 | CB9: 0.07 | CC9: -1.73 | CD9: -3.29 | CE9: -4.13 | CF9: -3.53 | CG9: -0.23 | CH9: 3.72 | CI9: 5.69 | CJ9: 7.62 | CK9: 8.15 | CL9: 5.18 | CM9: 1.07 | CN9: 3.9 | CO9: -4.7 | CP9: -2.83 | CQ9: -7.54 | CR9: -6 | CS9: 1.72 | CT9: 9.81 | CU9: 3.43 | CV9: 5.27 | CW9: 1.7 | CX9: 2.92 | CY9: 2.77 | CZ9: -0.29 | DA9: -1.95 | DB9: -8.31 | DC9: -3.96 | DD9: -4.31 | DE9: -2.06 | DF9: -3.71 | DG9: 8.68 | DH9: 9.61 | DI9: 1.97 | DJ9: 3.9 | DK9: 1.77 | DL9: 3.25 | DM9: -2.98 | DN9: -4.67 | DO9: -5.18 | DP9: -6.22 | DQ9: 4.91 | DR9: 4.65 | DS9: 1.52 | DT9: 1.13 | DU9: 1.17 | DV9: 2.34 | DW9: -0.32 | DX9: 1.5 | DY9: 0.58 | DZ9: -1.89 | EA9: -5.15 | EB9: -6.92 | EC9: 2.48 | ED9: -0.81 | EE9: -5.02 | EF9: -9.15 | EG9: -0.18 | EH9: 1.84 | EI9: 8.12 | EJ9: 20.3 | EK9: 2.88 | EL9: -0.32 | EM9: -4.98 | EN9: -8.08 | EO9: 4.35 | EP9: 18.2 | EQ9: 4.2 | ER9: 7.07 | ES9: 4.24 | ET9: 3.03 | EU9: -1.9 | EV9: 0.38 | EW9: -3.78 | EX9: 3.6 | EY9: -1.07 | EZ9: -1.11 | FA9: 0.97 | FB9: -11.54 | FC9: -3.53 | FD9: -6.38 | FE9: -3.27 | FF9: 0.43 | FG9: -4.3 | FH9: 13.4 | FI9: 9.55 | FJ9: 3.78 | FK9: -2 | FL9: -11.91 | FM9: -25.01 | FN9: -11.16 | FO9: -6.85 | FP9: 13.09 | FQ9: 9.41 | FR9: 22.27 | FS9: 13.53 | FT9: 7.68 | FU9: 15.54 | FV9: 1.35 | FW9: -2.41 | FX9: -3.02 | FY9: -4.88 | FZ9: 4.53 | GA9: 3.02 | GB9: -3.75 | GC9: -2.94 | GD9: 2.81 | GE9: -0.23 | GF9: 4.18 | GG9: 5.49 | GH9: -2.5 | GI9: -5.54
A10: Feijão-Branco | B10: Alimentos | C10: 0 | D10: 0 | E10: 0 | F10: 0 | G10: 0 | H10: 0 | I10: 0 | J10: 0 | K10: 0 | L10: 0 | M10: 0 | N10: 0 | O10: 0 | P10: 0 | Q10: 0 | R10: 0 | S10: 0 | T10: 0 | U10: 0 | V10: 0 | W10: 0 | X10: 0 | Y10: 0 | Z10: 0 | AA10: 0 | AB10: 0 | AC10: 0 | AD10: 8.13 | AE10: 5.02 | AF10: 7.58 | AG10: 3.23 | AH10: 2.01 | AI10: -5.66 | AJ10: -9.08 | AK10: -8.27 | AL10: 1.57 | AM10: 29.25 | AN10: 21.73 | AO10: 22.52 | AP10: -10.34 | AQ10: 2.35 | AR10: -5.56 | AS10: -0.54 | AT10: 2.92 | AU10: -6.48 | AV10: -0.14 | AW10: 5.79 | AX10: 0 | AY10: 0 | AZ10: 0 | BA10: 0 | BB10: 0 | BC10: 0 | BD10: 0 | BE10: 0 | BF10: 0 | BG10: 0 | BH10: 0 | BI10: 0 | BJ10: 0 | BK10: 0 | BL10: 0 | BM10: 0 | BN10: 0 | BO10: 0 | BP10: 0 | BQ10: 0 | BR10: 0 | BS10: 0 | BT10: 0 | BU10: 0 | BV10: 0 | BW10: 0 | BX10: 0 | BY10: 0 | BZ10: 0 | CA10: 0 | CB10: 0 | CC10: 0 | CD10: 0 | CE10: 0 | CF10: 0 | CG10: 0 | CH10: 0 | CI10: 0 | CJ10: 0 | CK10: 0 | CL10: 0 | CM10: 0 | CN10: 0 | CO10: 0 | CP10: 0 | CQ10: 0 | CR10: 0 | CS10: 0 | CT10: 0 | CU10: 0 | CV10: 0 | CW10: 0 | CX10: 0 | CY10: 0 | CZ10: 0 | DA10: 0 | DB10: 0 | DC10: 0 | DD10: 0 | DE10: 0 | DF10: 0 | DG10: 0 | DH10: 0 | DI10: 0 | DJ10: 0 | DK10: 0 | DL10: 0 | DM10: 0 | DN10: 0 | DO10: 0 | DP10: 0 | DQ10: 0 | DR10: 0 | DS10: 0 | DT10: 0 | DU10: 0 | DV10: 0 | DW10: 0 | DX10: 0 | DY10: 0 | DZ10: 0 | EA10: 0 | EB10: 0 | EC10: 0 | ED10: 0 | EE10: 0 | EF10: 0 | EG10: 0 | EH10: 0 | EI10: 0 | EJ10: 0 | EK10: 0 | EL10: 0 | EM10: 0 | EN10: 0 | EO10: 0 | EP10: 0 | EQ10: 0 | ER10: 0 | ES10: 0 | ET10: 0 | EU10: 0 | EV10: 0 | EW10: 0 | EX10: 0 | EY10: 0 | EZ10: 0 | FA10: 0 | FB10: 0 | FC10: 0 | FD10: 0 | FE10: 0 | FF10: 0 | FG10: 0 | FH10: 0 | FI10: 0 | FJ10: 0 | FK10: 0 | FL10: 0 | FM10: 0 | FN10: 0 | FO10: 0 | FP10: 0 | FQ10: 0 | FR10: 0 | FS10: 0 | FT10: 0 | FU10: 0 | FV10: 0 | FW10: 0 | FX10: 0 | FY10: 0 | FZ10: 0 | GA10: 0 | GB10: 0 | GC10: 0 | GD10: 0 | GE10: 0 | GF10: 0 | GG10: 0 | GH10: 0 | GI10: 0
A11: Fava | B11: Alimentos | C11: 0 | D11: 0 | E11: 0 | F11: 0 | G11: 0 | H11: 0 | I11: 0 | J11: 0 | K11: 0 | L11: 0 | M11: 0 | N11: 0 | O11: 0 | P11: 0 | Q11: 0 | R11: 0 | S11: 0 | T11: 0 | U11: 0 | V11: 0 | W11: 0 | X11: 0 | Y11: 0 | Z11: 0 | AA11: 0 | AB11: 0 | AC11: 0 | AD11: 0 | AE11: 0 | AF11: 0 | AG11: 0 | AH11: 0 | AI11: 0 | AJ11: 0 | AK11: 0 | AL11: 0 | AM11: 0 | AN11: 0 | AO11: 0 | AP11: 0 | AQ11: 0 | AR11: 0 | AS11: 0 | AT11: 0 | AU11: 0 | AV11: 0 | AW11: 0 | AX11: 0 | AY11: 0 | AZ11: 0 | BA11: 0 | BB11: 0 | BC11: 0 | BD11: 0 | BE11: 0 | BF11: 0 | BG11: 0 | BH11: 0 | BI11: 0 | BJ11: 0 | BK11: 0 | BL11: 0 | BM11: 0 | BN11: 0 | BO11: 0 | BP11: 0 | BQ11: 0 | BR11: 0 | BS11: 0 | BT11: 0 | BU11: 0 | BV11: 0 | BW11: 0 | BX11: 0 | BY11: 0 | BZ11: 0 | CA11: 0 | CB11: 0 | CC11: 0 | CD11: 0 | CE11: 0 | CF11: 0 | CG11: 0 | CH11: 0 | CI11: 0 | CJ11: 0 | CK11: 0 | CL11: 0 | CM11: 0 | CN11: 0 | CO11: 0 | CP11: 0 | CQ11: 0 | CR11: 0 | CS11: 0 | CT11: 0 | CU11: 0 | CV11: 0 | CW11: 0 | CX11: 0 | CY11: 0 | CZ11: 0 | DA11: 0 | DB11: 0 | DC11: 0 | DD11: 0 | DE11: 0 | DF11: 0 | DG11: 0 | DH11: 0 | DI11: 0 | DJ11: 0 | DK11: 0 | DL11: 0 | DM11: 0 | DN11: 0 | DO11: 0 | DP11: 0 | DQ11: 0 | DR11: 0 | DS11: 0 | DT11: 0 | DU11: 0 | DV11: -5.05 | DW11: 1.1 | DX11: 2.12 | DY11: 8.31 | DZ11: -0.75 | EA11: 6.42 | EB11: -5.52 | EC11: 0.12 | ED11: 4.21 | EE11: 4.71 | EF11: 1.82 | EG11: -5.45 | EH11: 20.41 | EI11: 1.47 | EJ11: 4.8 | EK11: 5.33 | EL11: 3.19 | EM11: 6.55 | EN11: 0.53 | EO11: 6.82 | EP11: -4.71 | EQ11: -0.96 | ER11: 3.81 | ES11: -7.24 | ET11: -1.95 | EU11: 5.79 | EV11: -2.82 | EW11: -5.5 | EX11: -0.81 | EY11: 2.16 | EZ11: -3.81 | FA11: -4.86 | FB11: -0.45 | FC11: -0.44 | FD11: -3.26 | FE11: -2.91 | FF11: -0.19 | FG11: -0.33 | FH11: 1.54 | FI11: 2.58 | FJ11: -2.85 | FK11: -0.07 | FL11: 1.46 | FM11: 1 | FN11: 3.29 | FO11: 5.48 | FP11: 6.19 | FQ11: 6.82 | FR11: 10.14 | FS11: -1.49 | FT11: -0.6 | FU11: 2.99 | FV11: -0.76 | FW11: -0.3 | FX11: 0.62 | FY11: 2.41 | FZ11: 0.6 | GA11: 3.25 | GB11: 0.74 | GC11: 0.31 | GD11: 4.05 | GE11: 0.07 | GF11: 1.57 | GG11: -2.8 | GH11: 0.94 | GI11: -0.08
A12: Farinha De Arroz | B12: Alimentos | C12: 0.24 | D12: 1.3 | E12: 0.81 | F12: -3.25 | G12: 0.14 | H12: 3.49 | I12: 0.29 | J12: 2.25 | K12: -1.41 | L12: 2.99 | M12: -4.56 | N12: -0.73 | O12: -3.94 | P12: 0.43 | Q12: -1.73 | R12: -0.25 | S12: 1.44 | T12: 2.4 | U12: 0.51 | V12: 0.29 | W12: -0.62 | X12: 0.12 | Y12: 0.34 | Z12: 0.39 | AA12: 4.78 | AB12: -4.62 | AC12: 1.25 | AD12: -0.34 | AE12: -0.52 | AF12: 0.42 | AG12: 0.84 | AH12: 1.37 | AI12: -4.31 | AJ12: -2.18 | AK12: -2.33 | AL12: 2.66 | AM12: -4.73 | AN12: 0.37 | AO12: 2.4 | AP12: 0.85 | AQ12: 1.56 | AR12: -0.01 | AS12: 0.32 | AT12: 0.53 | AU12: -0.1 | AV12: 0.23 | AW12: -0.44 | AX12: 0.14 | AY12: 1.3 | AZ12: 1.17 | BA12: 1.41 | BB12: -1.17 | BC12: 1.18 | BD12: 0.82 | BE12: -1.18 | BF12: 1.5 | BG12: 5.34 | BH12: -0.94 | BI12: 5.51 | BJ12: 0.95 | BK12: 0.53 | BL12: -0.46 | BM12: 0.15 | BN12: 1.2 | BO12: 0.74 | BP12: 0 | BQ12: 0.08 | BR12: 1.5 | BS12: -0.24 | BT12: 0.64 | BU12: 0.51 | BV12: -1.34 | BW12: 0.26 | BX12: 1.02 | BY12: -0.83 | BZ12: -0.57 | CA12: 0.44 | CB12: 1.21 | CC12: -1.55 | CD12: -0.16 | CE12: -0.95 | CF12: 0.36 | CG12: -1.54 | CH12: 2.18 | CI12: 2.1 | CJ12: 2.13 | CK12: 4.3 | CL12: 0.17 | CM12: -4.64 | CN12: -2.5 | CO12: -2.27 | CP12: 2.1 | CQ12: 2.14 | CR12: 0.97 | CS12: -0.09 | CT12: -0.32 | CU12: 2.18 | CV12: 0.42 | CW12: -1.51 | CX12: 0.48 | CY12: -0.22 | CZ12: 0.78 | DA12: 0.22 | DB12: 0.97 | DC12: 2.14 | DD12: 4.19 | DE12: 3.69 | DF12: 0.67 | DG12: 0.93 | DH12: -0.27 | DI12: 3.13 | DJ12: 0.83 | DK12: -0.66 | DL12: 0.64 | DM12: 1.29 | DN12: -0.42 | DO12: 3.42 | DP12: 1.6 | DQ12: -1.17 | DR12: 4.07 | DS12: 0.37 | DT12: -0.77 | DU12: -0.35 | DV12: -0.22 | DW12: -0.36 | DX12: 0.62 | DY12: 1.11 | DZ12: -0.94 | EA12: -0.81 | EB12: -0.44 | EC12: 3.17 | ED12: 2.05 | EE12: -0.34 | EF12: -0.36 | EG12: -2.4 | EH12: 3.82 | EI12: 0.99 | EJ12: -0.13 | EK12: 1.72 | EL12: -2.23 | EM12: -0.28 | EN12: 0.34 | EO12: 0.7 | EP12: 0.74 | EQ12: -0.07 | ER12: -1.3 | ES12: 1.96 | ET12: -1.5 | EU12: 2.1 | EV12: -0.99 | EW12: 0.01 | EX12: -1 | EY12: 2.86 | EZ12: 2.22 | FA12: 3.64 | FB12: -0.99 | FC12: -0.18 | FD12: 0.8 | FE12: 1.21 | FF12: -0.63 | FG12: 1.1 | FH12: 3.56 | FI12: 0.39 | FJ12: 1.25 | FK12: 0.61 | FL12: 0.27 | FM12: 4.27 | FN12: 0.45 | FO12: -0.69 | FP12: -1.1 | FQ12: 1.96 | FR12: -1.71 | FS12: -0.79 | FT12: -0.86 | FU12: -0.15 | FV12: 0.81 | FW12: 0.9 | FX12: 0.3 | FY12: 0.96 | FZ12: -0.14 | GA12: 1.72 | GB12: 0.99 | GC12: 0.79 | GD12: -0.2 | GE12: -1.12 | GF12: 2.12 | GG12: 0.04 | GH12: -1.48 | GI12: 3.08
... A534: Tv A Cabo | B534: Serviços | C534: 0 | D534: 0 | E534: 0 | F534: 0 | G534: 0 | H534: 0 | I534: 0 | J534: 0 | K534: 0 | L534: 0 | M534: 0 | N534: 0 | O534: 0 | P534: 0 | Q534: 0 | R534: 0 | S534: 0 | T534: 0 | U534: 0 | V534: 0 | W534: 0 | X534: 0 | Y534: 0 | Z534: 0 | AA534: 0 | AB534: 0 | AC534: 0 | AD534: 0 | AE534: 0 | AF534: 0 | AG534: 0 | AH534: 0 | AI534: 0 | AJ534: 0 | AK534: 0 | AL534: 0 | AM534: 0 | AN534: 0 | AO534: 0 | AP534: 0 | AQ534: 0 | AR534: 0 | AS534: 0 | AT534: 0 | AU534: 0 | AV534: 0 | AW534: 0 | AX534: 0 | AY534: 0 | AZ534: 0 | BA534: 0 | BB534: 0 | BC534: 0 | BD534: 0 | BE534: 0 | BF534: 0 | BG534: 0 | BH534: 0 | BI534: 0 | BJ534: 0 | BK534: 0 | BL534: 0 | BM534: 0 | BN534: 0 | BO534: 0 | BP534: 0 | BQ534: 0 | BR534: 0 | BS534: 0 | BT534: 0 | BU534: 0 | BV534: 0 | BW534: 0 | BX534: 0 | BY534: 0 | BZ534: 0 | CA534: 0 | CB534: 0 | CC534: 0 | CD534: 0 | CE534: 0 | CF534: 0 | CG534: 0 | CH534: 0 | CI534: 0 | CJ534: 0 | CK534: 0 | CL534: 0 | CM534: 0 | CN534: 0 | CO534: 0 | CP534: 0 | CQ534: 0 | CR534: 0 | CS534: 0 | CT534: 0 | CU534: 0 | CV534: 0 | CW534: 0 | CX534: 0 | CY534: 0 | CZ534: 0 | DA534: 0 | DB534: 0 | DC534: 0 | DD534: 0 | DE534: 0 | DF534: 0 | DG534: 0 | DH534: 0 | DI534: 0 | DJ534: 0 | DK534: 0 | DL534: 0 | DM534: 0 | DN534: 0 | DO534: 0 | DP534: 0 | DQ534: 0 | DR534: 0 | DS534: 0 | DT534: 0 | DU534: 0 | DV534: 0.03 | DW534: 0.03 | DX534: 0.03 | DY534: 0.04 | DZ534: 0.04 | EA534: 0.04 | EB534: 0.04 | EC534: 0 | ED534: 0.11 | EE534: 0.29 | EF534: 0.94 | EG534: 2.63 | EH534: 0 | EI534: 0.04 | EJ534: 0.03 | EK534: 0.38 | EL534: 0.03 | EM534: 0.97 | EN534: 0.02 | EO534: 0.11 | EP534: 0.01 | EQ534: 0.02 | ER534: 0 | ES534: 0.18 | ET534: 0.12 | EU534: 0 | EV534: 1.87 | EW534: 0.62 | EX534: 0 | EY534: 0.13 | EZ534: 0.01 | FA534: 0.06 | FB534: 0.41 | FC534: 0.02 | FD534: 0.91 | FE534: 0.32 | FF534: 0.06 | FG534: 1.39 | FH534: 0.07 | FI534: 1.15 | FJ534: 0.26 | FK534: 0.07 | FL534: 2.33 | FM534: 0.03 | FN534: 0.09 | FO534: 0.16 | FP534: 0.37 | FQ534: 0.15 | FR534: 0.03 | FS534: 0.05 | FT534: 0.09 | FU534: 0.28 | FV534: 0.38 | FW534: 0.01 | FX534: 0.02 | FY534: 0.29 | FZ534: 0.09 | GA534: 0.02 | GB534: 0.02 | GC534: -0.15 | GD534: 0.02 | GE534: 0.02 | GF534: 0.13 | GG534: 0.01 | GH534: 0.68 | GI534: 0.01

Sheet Peso Mensal
A1: Subitem | B1: Categoria | C1: 202203 | D1: 202202 | E1: 202201 | F1: 202112 | G1: 202111 | H1: 202110 | I1: 202109 | J1: 202108 | K1: 202107 | L1: 202106 | M1: 202105 | N1: 202104 | O1: 202103 | P1: 202102 | Q1: 202101 | R1: 202012 | S1: 202011 | T1: 202010 | U1: 202009 | V1: 202008 | W1: 202007 | X1: 202006 | Y1: 202005 | Z1: 202004 | AA1: 202003 | AB1: 202002 | AC1: 202001 | AD1: 201912 | AE1: 201911 | AF1: 201910 | AG1: 201909 | AH1: 201908 | AI1: 201907 | AJ1: 201906 | AK1: 201905 | AL1: 201904 | AM1: 201903 | AN1: 201902 | AO1: 201901 | AP1: 201812 | AQ1: 201811 | AR1: 201810 | AS1: 201809 | AT1: 201808 | AU1: 201807 | AV1: 201806 | AW1: 201805 | AX1: 201804 | AY1: 201803 | AZ1: 201802 | BA1: 201801 | BB1: 201712 | BC1: 201711 | BD1: 201710 | BE1: 201709 | BF1: 201708 | BG1: 201707 | BH1: 201706 | BI1: 201705 | BJ1: 201704 | BK1: 201703 | BL1: 201702 | BM1: 201701 | BN1: 201612 | BO1: 201611 | BP1: 201610 | BQ1: 201609 | BR1: 201608 | BS1: 201607 | BT1: 201606 | BU1: 201605 | BV1: 201604 | BW1: 201603 | BX1: 201602 | BY1: 201601 | BZ1: 201512 | CA1: 201511 | CB1: 201510 | CC1: 201509 | CD1: 201508 | CE1: 201507 | CF1: 201506 | CG1: 201505 | CH1: 201504 | CI1: 201503 | CJ1: 201502 | CK1: 201501 | CL1: 201412 | CM1: 201411 | CN1: 201410 | CO1: 201409 | CP1: 201408 | CQ1: 201407 | CR1: 201406 | CS1: 201405 | CT1: 201404 | CU1: 201403 | CV1: 201402 | CW1: 201401 | CX1: 201312 | CY1: 201311 | CZ1: 201310 | DA1: 201309 | DB1: 201308 | DC1: 201307 | DD1: 201306 | DE1: 201305 | DF1: 201304 | DG1: 201303 | DH1: 201302 | DI1: 201301 | DJ1: 201212 | DK1: 201211 | DL1: 201210 | DM1: 201209 | DN1: 201208 | DO1: 201207 | DP1: 201206 | DQ1: 201205 | DR1: 201204 | DS1: 201203 | DT1: 201202 | DU1: 201201 | DV1: 201112 | DW1: 201111 | DX1: 201110 | DY1: 201109 | DZ1: 201108 | EA1: 201107 | EB1: 201106 | EC1: 201105 | ED1: 201104 | EE1: 201103 | EF1: 201102 | EG1: 201101 | EH1: 201012 | EI1: 201011 | EJ1: 201010 | EK1: 201009 | EL1: 201008 | EM1: 201007 | EN1: 201006 | EO1: 201005 | EP1: 201004 | EQ1: 201003 | ER1: 201002 | ES1: 201001 | ET1: 200912 | EU1: 200911 | EV1: 200910 | EW1: 200909 | EX1: 200908 | EY1: 200907 | EZ1: 200906 | FA1: 200905 | FB1: 200904 | FC1: 200903 | FD1: 200902 | FE1: 200901 | FF1: 200812 | FG1: 200811 | FH1: 200810 | FI1: 200809 | FJ1: 200808 | FK1: 200807 | FL1: 200806 | FM1: 200805 | FN1: 200804 | FO1: 200803 | FP1: 200802 | FQ1: 200801 | FR1: 200712 | FS1: 200711 | FT1: 200710 | FU1: 200709 | FV1: 200708 | FW1: 200707 | FX1: 200706 | FY1: 200705 | FZ1: 200704 | GA1: 200703 | GB1: 200702 | GC1: 200701 | GD1: 200612 | GE1: 200611 | GF1: 200610 | GG1: 200609 | GH1: 200608 | GI1: 200607
A2: Índice Geral | B2: Índice Geral | C2: 100 | D2: 100 | E2: 100 | F2: 100 | G2: 100 | H2: 100 | I2: 100 | J2: 100 | K2: 100 | L2: 100 | M2: 100 | N2: 100 | O2: 100 | P2: 100 | Q2: 100 | R2: 100 | S2: 100 | T2: 100 | U2: 100 | V2: 100 | W2: 100 | X2: 100 | Y2: 100 | Z2: 100 | AA2: 100 | AB2: 100 | AC2: 100 | AD2: 100 | AE2: 100 | AF2: 100 | AG2: 100 | AH2: 100 | AI2: 100 | AJ2: 100 | AK2: 100 | AL2: 100 | AM2: 100 | AN2: 100 | AO2: 100 | AP2: 100 | AQ2: 100 | AR2: 100 | AS2: 100 | AT2: 100 | AU2: 100 | AV2: 100 | AW2: 100 | AX2: 100 | AY2: 100 | AZ2: 100 | BA2: 100 | BB2: 100 | BC2: 100 | BD2: 100 | BE2: 100 | BF2: 100 | BG2: 100 | BH2: 100 | BI2: 100 | BJ2: 100 | BK2: 100 | BL2: 100 | BM2: 100 | BN2: 100 | BO2: 100 | BP2: 100 | BQ2: 100 | BR2: 100 | BS2: 100 | BT2: 100 | BU2: 100 | BV2: 100 | BW2: 100 | BX2: 100 | BY2: 100 | BZ2: 100 | CA2: 100 | CB2: 100 | CC2: 100 | CD2: 100 | CE2: 100 | CF2: 100 | CG2: 100 | CH2: 100 | CI2: 100 | CJ2: 100 | CK2: 100 | CL2: 100 | CM2: 100 | CN2: 100 | CO2: 100 | CP2: 100 | CQ2: 100 | CR2: 100 | CS2: 100 | CT2: 100 | CU2: 100 | CV2: 100 | CW2: 100 | CX2: 100 | CY2: 100 | CZ2: 100 | DA2: 100 | DB2: 100 | DC2: 100 | DD2: 100 | DE2: 100 | DF2: 100 | DG2: 100 | DH2: 100 | DI2: 100 | DJ2: 100 | DK2: 100 | DL2: 100 | DM2: 100 | DN2: 100 | DO2: 100 | DP2: 100 | DQ2: 100 | DR2: 100 | DS2: 100 | DT2: 100 | DU2: 100 | DV2: 100 | DW2: 100 | DX2: 100 | DY2: 100 | DZ2: 100 | EA2: 100 | EB2: 100 | EC2: 100 | ED2: 100 | EE2: 100 | EF2: 100 | EG2: 100 | EH2: 100 | EI2: 100 | EJ2: 100 | EK2: 100 | EL2: 100 | EM2: 100 | EN2: 100 | EO2: 100 | EP2: 100 | EQ2: 100 | ER2: 100 | ES2: 100 | ET2: 100 | EU2: 100 | EV2: 100 | EW2: 100 | EX2: 100 | EY2: 100 | EZ2: 100 | FA2: 100 | FB2: 100 | FC2: 100 | FD2: 100 | FE2: 100 | FF2: 100 | FG2: 100 | FH2: 100 | FI2: 100 | FJ2: 100 | FK2: 100 | FL2: 100 | FM2: 100 | FN2: 100 | FO2: 100 | FP2: 100 | FQ2: 100 | FR2: 100 | FS2: 100 | FT2: 100 | FU2: 100 | FV2: 100 | FW2: 100 | FX2: 100 | FY2: 100 | FZ2: 100 | GA2: 100 | GB2: 100 | GC2: 100 | GD2: 100 | GE2: 100 | GF2: 100 | GG2: 100 | GH2: 100 | GI2: 100
A3: Arroz | B3: Alimentos | C3: 0.5795 | D3: 0.5847 | E3: 0.6042 | F3: 0.6195 | G3: 0.6486 | H3: 0.6661 | I3: 0.6803 | J3: 0.7007 | K3: 0.7243 | L3: 0.7358 | M3: 0.7506 | N3: 0.757 | O3: 0.7805 | P3: 0.7995 | Q3: 0.7995 | R3: 0.7806 | S3: 0.7412 | T3: 0.6596 | U3: 0.563 | V3: 0.5474 | W3: 0.5377 | X3: 0.5244 | Y3: 0.5121 | Z3: 0.4915 | AA3: 0.4842 | AB3: 0.4806 | AC3: 0.4753 | AD3: 0.5792 | AE3: 0.5784 | AF3: 0.5786 | AG3: 0.5748 | AH3: 0.5714 | AI3: 0.5694 | AJ3: 0.5667 | AK3: 0.5698 | AL3: 0.5741 | AM3: 0.5808 | AN3: 0.5909 | AO3: 0.5915 | AP3: 0.5995 | AQ3: 0.5964 | AR3: 0.5927 | AS3: 0.5828 | AT3: 0.568 | AU3: 0.5582 | AV3: 0.5486 | AW3: 0.5569 | AX3: 0.5435 | AY3: 0.5506 | AZ3: 0.5579 | BA3: 0.5607 | BB3: 0.5632 | BC3: 0.5701 | BD3: 0.5793 | BE3: 0.5825 | BF3: 0.589 | BG3: 0.5994 | BH3: 0.6036 | BI3: 0.6174 | BJ3: 0.6288 | BK3: 0.6376 | BL3: 0.6434 | BM3: 0.6467 | BN3: 0.6473 | BO3: 0.6492 | BP3: 0.6485 | BQ3: 0.642 | BR3: 0.6264 | BS3: 0.6017 | BT3: 0.5934 | BU3: 0.5934 | BV3: 0.5952 | BW3: 0.5923 | BX3: 0.5929 | BY3: 0.5923 | BZ3: 0.5884 | CA3: 0.5765 | CB3: 0.5602 | CC3: 0.5611 | CD3: 0.5638 | CE3: 0.5687 | CF3: 0.5728 | CG3: 0.575 | CH3: 0.5839 | CI3: 0.589 | CJ3: 0.5938 | CK3: 0.5976 | CL3: 0.5916 | CM3: 0.5952 | CN3: 0.5909 | CO3: 0.5901 | CP3: 0.5981 | CQ3: 0.5954 | CR3: 0.5905 | CS3: 0.5842 | CT3: 0.5866 | CU3: 0.5905 | CV3: 0.5887 | CW3: 0.5854 | CX3: 0.5857 | CY3: 0.5952 | CZ3: 0.5996 | DA3: 0.6001 | DB3: 0.6022 | DC3: 0.6025 | DD3: 0.5998 | DE3: 0.6094 | DF3: 0.6244 | DG3: 0.6383 | DH3: 0.6458 | DI3: 0.6517 | DJ3: 0.6493 | DK3: 0.628 | DL3: 0.5752 | DM3: 0.5347 | DN3: 0.5277 | DO3: 0.5265 | DP3: 0.5216 | DQ3: 0.5127 | DR3: 0.5137 | DS3: 0.5124 | DT3: 0.5094 | DU3: 0.5054 | DV3: 0.4663 | DW3: 0.4665 | DX3: 0.4673 | DY3: 0.4607 | DZ3: 0.4541 | EA3: 0.4603 | EB3: 0.4695 | EC3: 0.4798 | ED3: 0.4939 | EE3: 0.5025 | EF3: 0.5144 | EG3: 0.5227 | EH3: 0.5248 | EI3: 0.5358 | EJ3: 0.5462 | EK3: 0.547 | EL3: 0.5528 | EM3: 0.5592 | EN3: 0.5625 | EO3: 0.5658 | EP3: 0.5764 | EQ3: 0.5822 | ER3: 0.5616 | ES3: 0.5478 | ET3: 0.5547 | EU3: 0.5585 | EV3: 0.5606 | EW3: 0.5662 | EX3: 0.5655 | EY3: 0.5684 | EZ3: 0.589 | FA3: 0.6058 | FB3: 0.6248 | FC3: 0.6375 | FD3: 0.6461 | FE3: 0.6579 | FF3: 0.6717 | FG3: 0.6733 | FH3: 0.6665 | FI3: 0.6737 | FJ3: 0.6866 | FK3: 0.6938 | FL3: 0.6359 | FM3: 0.5352 | FN3: 0.5275 | FO3: 0.5261 | FP3: 0.5203 | FQ3: 0.5201 | FR3: 0.5295 | FS3: 0.5297 | FT3: 0.5206 | FU3: 0.5037 | FV3: 0.4983 | FW3: 0.502 | FX3: 0.5025 | FY3: 0.5074 | FZ3: 0.5146 | GA3: 0.5325 | GB3: 0.5478 | GC3: 0.5545 | GD3: 0.5333 | GE3: 0.508 | GF3: 0.506 | GG3: 0.5079 | GH3: 0.4981 | GI3: 0.4784
A4: Feijão-Mulatinho | B4: Alimentos | C4: 0.0147 | D4: 0.0136 | E4: 0.0141 | F4: 0.0143 | G4: 0.0145 | H4: 0.015 | I4: 0.0156 | J4: 0.0158 | K4: 0.0152 | L4: 0.0151 | M4: 0.0151 | N4: 0.0146 | O4: 0.0147 | P4: 0.0147 | Q4: 0.0145 | R4: 0.0149 | S4: 0.015 | T4: 0.0146 | U4: 0.0152 | V4: 0.0155 | W4: 0.0154 | X4: 0.0145 | Y4: 0.0142 | Z4: 0.0123 | AA4: 0.0116 | AB4: 0.0121 | AC4: 0.0116 | AD4: 0.0202 | AE4: 0.0221 | AF4: 0.0231 | AG4: 0.0252 | AH4: 0.0252 | AI4: 0.0253 | AJ4: 0.0269 | AK4: 0.0278 | AL4: 0.0304 | AM4: 0.0262 | AN4: 0.0215 | AO4: 0.0188 | AP4: 0.0183 | AQ4: 0.0182 | AR4: 0.0181 | AS4: 0.0182 | AT4: 0.0184 | AU4: 0.0181 | AV4: 0.0187 | AW4: 0.0186 | AX4: 0.0225 | AY4: 0.0222 | AZ4: 0.0222 | BA4: 0.0227 | BB4: 0.0238 | BC4: 0.0239 | BD4: 0.0293 | BE4: 0.0365 | BF4: 0.0412 | BG4: 0.0415 | BH4: 0.0415 | BI4: 0.0418 | BJ4: 0.0414 | BK4: 0.0436 | BL4: 0.0419 | BM4: 0.0421 | BN4: 0.0442 | BO4: 0.0447 | BP4: 0.0472 | BQ4: 0.048 | BR4: 0.0465 | BS4: 0.0394 | BT4: 0.0271 | BU4: 0.0271 | BV4: 0.0269 | BW4: 0.0263 | BX4: 0.0242 | BY4: 0.0224 | BZ4: 0.0215 | CA4: 0.0211 | CB4: 0.0219 | CC4: 0.0228 | CD4: 0.0236 | CE4: 0.0218 | CF4: 0.0217 | CG4: 0.0222 | CH4: 0.021 | CI4: 0.0207 | CJ4: 0.019 | CK4: 0.0186 | CL4: 0.0174 | CM4: 0.0179 | CN4: 0.0187 | CO4: 0.0198 | CP4: 0.0225 | CQ4: 0.0228 | CR4: 0.0232 | CS4: 0.0231 | CT4: 0.0226 | CU4: 0.0234 | CV4: 0.0236 | CW4: 0.0252 | CX4: 0.0257 | CY4: 0.0264 | CZ4: 0.0286 | DA4: 0.0357 | DB4: 0.0401 | DC4: 0.0398 | DD4: 0.0417 | DE4: 0.036 | DF4: 0.0336 | DG4: 0.0336 | DH4: 0.0334 | DI4: 0.0312 | DJ4: 0.0321 | DK4: 0.0324 | DL4: 0.0334 | DM4: 0.0361 | DN4: 0.038 | DO4: 0.0366 | DP4: 0.0339 | DQ4: 0.0289 | DR4: 0.0257 | DS4: 0.0255 | DT4: 0.0249 | DU4: 0.0216 | DV4: 0.0261 | DW4: 0.0263 | DX4: 0.026 | DY4: 0.0263 | DZ4: 0.0269 | EA4: 0.0257 | EB4: 0.0262 | EC4: 0.0267 | ED4: 0.0257 | EE4: 0.0257 | EF4: 0.0259 | EG4: 0.0274 | EH4: 0.0293 | EI4: 0.0299 | EJ4: 0.0269 | EK4: 0.0261 | EL4: 0.0276 | EM4: 0.0264 | EN4: 0.0259 | EO4: 0.0241 | EP4: 0.0219 | EQ4: 0.0208 | ER4: 0.0208 | ES4: 0.0212 | ET4: 0.0223 | EU4: 0.0221 | EV4: 0.0229 | EW4: 0.0245 | EX4: 0.0259 | EY4: 0.0277 | EZ4: 0.0286 | FA4: 0.029 | FB4: 0.0292 | FC4: 0.0314 | FD4: 0.031 | FE4: 0.0323 | FF4: 0.0368 | FG4: 0.0401 | FH4: 0.0397 | FI4: 0.0409 | FJ4: 0.0437 | FK4: 0.0448 | FL4: 0.0435 | FM4: 0.0451 | FN4: 0.048 | FO4: 0.0489 | FP4: 0.0456 | FQ4: 0.0392 | FR4: 0.0297 | FS4: 0.0228 | FT4: 0.0198 | FU4: 0.0192 | FV4: 0.0189 | FW4: 0.0184 | FX4: 0.0184 | FY4: 0.0185 | FZ4: 0.0176 | GA4: 0.0173 | GB4: 0.0175 | GC4: 0.0175 | GD4: 0.0173 | GE4: 0.0167 | GF4: 0.0165 | GG4: 0.0184 | GH4: 0.0193 | GI4: 0.0212
A5: Feijão-Preto | B5: Alimentos | C5: 0.0597 | D5: 0.0586 | E5: 0.0598 | F5: 0.0606 | G5: 0.0635 | H5: 0.0651 | I5: 0.0672 | J5: 0.0689 | K5: 0.0708 | L5: 0.0712 | M5: 0.0723 | N5: 0.0699 | O5: 0.07 | P5: 0.0699 | Q5: 0.0679 | R5: 0.0668 | S5: 0.0658 | T5: 0.0647 | U5: 0.0625 | V5: 0.0628 | W5: 0.0622 | X5: 0.0583 | Y5: 0.0541 | Z5: 0.049 | AA5: 0.0484 | AB5: 0.0473 | AC5: 0.0486 | AD5: 0.0655 | AE5: 0.0669 | AF5: 0.0689 | AG5: 0.0702 | AH5: 0.0708 | AI5: 0.0735 | AJ5: 0.0802 | AK5: 0.0879 | AL5: 0.0919 | AM5: 0.0824 | AN5: 0.0675 | AO5: 0.0653 | AP5: 0.0649 | AQ5: 0.0654 | AR5: 0.0637 | AS5: 0.0634 | AT5: 0.0632 | AU5: 0.0641 | AV5: 0.064 | AW5: 0.0653 | AX5: 0.0665 | AY5: 0.0684 | AZ5: 0.0695 | BA5: 0.07 | BB5: 0.0707 | BC5: 0.0731 | BD5: 0.076 | BE5: 0.0782 | BF5: 0.0836 | BG5: 0.0793 | BH5: 0.0776 | BI5: 0.0808 | BJ5: 0.0883 | BK5: 0.0974 | BL5: 0.1079 | BM5: 0.1125 | BN5: 0.113 | BO5: 0.114 | BP5: 0.116 | BQ5: 0.1206 | BR5: 0.118 | BS5: 0.0838 | BT5: 0.0773 | BU5: 0.0773 | BV5: 0.077 | BW5: 0.0734 | BX5: 0.0682 | BY5: 0.0671 | BZ5: 0.0672 | CA5: 0.0682 | CB5: 0.0675 | CC5: 0.0679 | CD5: 0.0692 | CE5: 0.0725 | CF5: 0.0737 | CG5: 0.0758 | CH5: 0.0782 | CI5: 0.079 | CJ5: 0.077 | CK5: 0.0759 | CL5: 0.0739 | CM5: 0.0785 | CN5: 0.0786 | CO5: 0.0782 | CP5: 0.0811 | CQ5: 0.0847 | CR5: 0.0882 | CS5: 0.0855 | CT5: 0.0827 | CU5: 0.0838 | CV5: 0.0862 | CW5: 0.0876 | CX5: 0.0843 | CY5: 0.0857 | CZ5: 0.0857 | DA5: 0.0859 | DB5: 0.0831 | DC5: 0.0787 | DD5: 0.0758 | DE5: 0.0741 | DF5: 0.0748 | DG5: 0.0737 | DH5: 0.0722 | DI5: 0.0725 | DJ5: 0.0717 | DK5: 0.0732 | DL5: 0.0724 | DM5: 0.0714 | DN5: 0.0719 | DO5: 0.0681 | DP5: 0.0659 | DQ5: 0.0641 | DR5: 0.064 | DS5: 0.0636 | DT5: 0.0562 | DU5: 0.0537 | DV5: 0.0856 | DW5: 0.0857 | DX5: 0.0851 | DY5: 0.0857 | DZ5: 0.0856 | EA5: 0.087 | EB5: 0.0885 | EC5: 0.0897 | ED5: 0.0902 | EE5: 0.0937 | EF5: 0.0975 | EG5: 0.1024 | EH5: 0.1051 | EI5: 0.1039 | EJ5: 0.0964 | EK5: 0.0952 | EL5: 0.0953 | EM5: 0.0951 | EN5: 0.0949 | EO5: 0.0882 | EP5: 0.0848 | EQ5: 0.085 | ER5: 0.0831 | ES5: 0.0835 | ET5: 0.0861 | EU5: 0.0887 | EV5: 0.09 | EW5: 0.0949 | EX5: 0.097 | EY5: 0.0984 | EZ5: 0.1076 | FA5: 0.1213 | FB5: 0.1391 | FC5: 0.158 | FD5: 0.1564 | FE5: 0.156 | FF5: 0.1683 | FG5: 0.1634 | FH5: 0.1523 | FI5: 0.156 | FJ5: 0.1594 | FK5: 0.152 | FL5: 0.1424 | FM5: 0.1418 | FN5: 0.144 | FO5: 0.1372 | FP5: 0.1213 | FQ5: 0.1001 | FR5: 0.0896 | FS5: 0.0811 | FT5: 0.074 | FU5: 0.0699 | FV5: 0.0677 | FW5: 0.0654 | FX5: 0.0649 | FY5: 0.0663 | FZ5: 0.0672 | GA5: 0.0699 | GB5: 0.0731 | GC5: 0.0751 | GD5: 0.0761 | GE5: 0.0772 | GF5: 0.0791 | GG5: 0.0839 | GH5: 0.0877 | GI5: 0.0906
A6: Feijão-Macáçar (Fradinho) | B6: Alimentos | C6: 0.0193 | D6: 0.0187 | E6: 0.0192 | F6: 0.0193 | G6: 0.0195 | H6: 0.0201 | I6: 0.0204 | J6: 0.0204 | K6: 0.0206 | L6: 0.0215 | M6: 0.0202 | N6: 0.0201 | O6: 0.0193 | P6: 0.0196 | Q6: 0.0192 | R6: 0.0185 | S6: 0.0185 | T6: 0.0185 | U6: 0.0161 | V6: 0.0158 | W6: 0.0153 | X6: 0.0149 | Y6: 0.0145 | Z6: 0.0137 | AA6: 0.0129 | AB6: 0.0127 | AC6: 0.0121 | AD6: 0 | AE6: 0 | AF6: 0 | AG6: 0 | AH6: 0 | AI6: 0 | AJ6: 0 | AK6: 0 | AL6: 0 | AM6: 0 | AN6: 0 | AO6: 0 | AP6: 0 | AQ6: 0 | AR6: 0 | AS6: 0 | AT6: 0 | AU6: 0 | AV6: 0 | AW6: 0 | AX6: 0 | AY6: 0 | AZ6: 0 | BA6: 0 | BB6: 0 | BC6: 0 | BD6: 0 | BE6: 0 | BF6: 0 | BG6: 0 | BH6: 0 | BI6: 0 | BJ6: 0 | BK6: 0 | BL6: 0 | BM6: 0 | BN6: 0 | BO6: 0 | BP6: 0 | BQ6: 0 | BR6: 0 | BS6: 0 | BT6: 0 | BU6: 0 | BV6: 0 | BW6: 0 | BX6: 0 | BY6: 0 | BZ6: 0 | CA6: 0 | CB6: 0 | CC6: 0 | CD6: 0 | CE6: 0 | CF6: 0 | CG6: 0 | CH6: 0 | CI6: 0 | CJ6: 0 | CK6: 0 | CL6: 0 | CM6: 0 | CN6: 0 | CO6: 0 | CP6: 0 | CQ6: 0 | CR6: 0 | CS6: 0 | CT6: 0 | CU6: 0 | CV6: 0 | CW6: 0 | CX6: 0 | CY6: 0 | CZ6: 0 | DA6: 0 | DB6: 0 | DC6: 0 | DD6: 0 | DE6: 0 | DF6: 0 | DG6: 0 | DH6: 0 | DI6: 0 | DJ6: 0 | DK6: 0 | DL6: 0 | DM6: 0 | DN6: 0 | DO6: 0 | DP6: 0 | DQ6: 0 | DR6: 0 | DS6: 0 | DT6: 0 | DU6: 0 | DV6: 0 | DW6: 0 | DX6: 0 | DY6: 0 | DZ6: 0 | EA6: 0 | EB6: 0 | EC6: 0 | ED6: 0 | EE6: 0 | EF6: 0 | EG6: 0 | EH6: 0 | EI6: 0 | EJ6: 0 | EK6: 0 | EL6: 0 | EM6: 0 | EN6: 0 | EO6: 0 | EP6: 0 | EQ6: 0 | ER6: 0 | ES6: 0 | ET6: 0 | EU6: 0 | EV6: 0 | EW6: 0 | EX6: 0 | EY6: 0 | EZ6: 0 | FA6: 0 | FB6: 0 | FC6: 0 | FD6: 0 | FE6: 0 | FF6: 0 | FG6: 0 | FH6: 0 | FI6: 0 | FJ6: 0 | FK6: 0 | FL6: 0 | FM6: 0 | FN6: 0 | FO6: 0 | FP6: 0 | FQ6: 0 | FR6: 0 | FS6: 0 | FT6: 0 | FU6: 0 | FV6: 0 | FW6: 0 | FX6: 0 | FY6: 0 | FZ6: 0 | GA6: 0 | GB6: 0 | GC6: 0 | GD6: 0 | GE6: 0 | GF6: 0 | GG6: 0 | GH6: 0 | GI6: 0
A7: Feijão-Carioca (Rajado) | B7: Alimentos | C7: 0.1297 | D7: 0.125 | E7: 0.1256 | F7: 0.13 | G7: 0.1341 | H7: 0.1378 | I7: 0.1397 | J7: 0.1421 | K7: 0.1446 | L7: 0.1443 | M7: 0.1474 | N7: 0.1469 | O7: 0.1479 | P7: 0.1515 | Q7: 0.15 | R7: 0.1476 | S7: 0.1478 | T7: 0.1486 | U7: 0.1501 | V7: 0.1599 | W7: 0.1706 | X7: 0.163 | Y7: 0.1495 | Z7: 0.127 | AA7: 0.1287 | AB7: 0.1337 | AC7: 0.135 | AD7: 0.1903 | AE7: 0.1794 | AF7: 0.1792 | AG7: 0.1845 | AH7: 0.1909 | AI7: 0.2097 | AJ7: 0.2462 | AK7: 0.2836 | AL7: 0.3137 | AM7: 0.2796 | AN7: 0.1854 | AO7: 0.1553 | AP7: 0.1376 | AQ7: 0.1386 | AR7: 0.1409 | AS7: 0.1396 | AT7: 0.1426 | AU7: 0.1469 | AV7: 0.1449 | AW7: 0.141 | AX7: 0.1397 | AY7: 0.1438 | AZ7: 0.1487 | BA7: 0.1541 | BB7: 0.1658 | BC7: 0.1815 | BD7: 0.1887 | BE7: 0.2087 | BF7: 0.2455 | BG7: 0.2603 | BH7: 0.2064 | BI7: 0.2003 | BJ7: 0.2038 | BK7: 0.2163 | BL7: 0.2528 | BM7: 0.2938 | BN7: 0.3418 | BO7: 0.415 | BP7: 0.4564 | BQ7: 0.4789 | BR7: 0.509 | BS7: 0.3866 | BT7: 0.2564 | BU7: 0.2564 | BV7: 0.248 | BW7: 0.2392 | BX7: 0.2261 | BY7: 0.2133 | BZ7: 0.2011 | CA7: 0.1968 | CB7: 0.1982 | CC7: 0.2004 | CD7: 0.2079 | CE7: 0.2049 | CF7: 0.2111 | CG7: 0.222 | CH7: 0.2271 | CI7: 0.2223 | CJ7: 0.2106 | CK7: 0.1807 | CL7: 0.1616 | CM7: 0.1622 | CN7: 0.1623 | CO7: 0.173 | CP7: 0.1803 | CQ7: 0.1927 | CR7: 0.2075 | CS7: 0.2083 | CT7: 0.2002 | CU7: 0.1806 | CV7: 0.1902 | CW7: 0.1993 | CX7: 0.2179 | CY7: 0.2379 | CZ7: 0.2638 | DA7: 0.3074 | DB7: 0.335 | DC7: 0.3525 | DD7: 0.3612 | DE7: 0.3378 | DF7: 0.3103 | DG7: 0.286 | DH7: 0.2691 | DI7: 0.2579 | DJ7: 0.2509 | DK7: 0.2578 | DL7: 0.2556 | DM7: 0.2613 | DN7: 0.2891 | DO7: 0.3114 | DP7: 0.3215 | DQ7: 0.2935 | DR7: 0.262 | DS7: 0.2602 | DT7: 0.2375 | DU7: 0.2074 | DV7: 0.1996 | DW7: 0.2024 | DX7: 0.207 | DY7: 0.1961 | DZ7: 0.1957 | EA7: 0.195 | EB7: 0.1968 | EC7: 0.1947 | ED7: 0.1785 | EE7: 0.1768 | EF7: 0.1992 | EG7: 0.2365 | EH7: 0.2847 | EI7: 0.3074 | EJ7: 0.236 | EK7: 0.2362 | EL7: 0.2661 | EM7: 0.2702 | EN7: 0.2635 | EO7: 0.2342 | EP7: 0.1645 | EQ7: 0.1497 | ER7: 0.1537 | ES7: 0.153 | ET7: 0.156 | EU7: 0.1634 | EV7: 0.1719 | EW7: 0.1836 | EX7: 0.1942 | EY7: 0.1829 | EZ7: 0.182 | FA7: 0.1945 | FB7: 0.214 | FC7: 0.2462 | FD7: 0.2563 | FE7: 0.2492 | FF7: 0.3084 | FG7: 0.3623 | FH7: 0.3469 | FI7: 0.3536 | FJ7: 0.377 | FK7: 0.3555 | FL7: 0.3099 | FM7: 0.3519 | FN7: 0.3969 | FO7: 0.4393 | FP7: 0.4154 | FQ7: 0.3736 | FR7: 0.2718 | FS7: 0.2217 | FT7: 0.192 | FU7: 0.1847 | FV7: 0.1767 | FW7: 0.1693 | FX7: 0.1467 | FY7: 0.1446 | FZ7: 0.1482 | GA7: 0.1527 | GB7: 0.1585 | GC7: 0.1606 | GD7: 0.1627 | GE7: 0.1585 | GF7: 0.1511 | GG7: 0.1546 | GH7: 0.1682 | GI7: 0.1866
A8: Milho (Em Grão) | B8: Alimentos | C8: 0.0119 | D8: 0.0119 | E8: 0.0116 | F8: 0.0116 | G8: 0.0116 | H8: 0.0114 | I8: 0.0109 | J8: 0.0108 | K8: 0.0111 | L8: 0.0112 | M8: 0.0112 | N8: 0.0108 | O8: 0.0109 | P8: 0.011 | Q8: 0.0109 | R8: 0.0108 | S8: 0.011 | T8: 0.0109 | U8: 0.0107 | V8: 0.0107 | W8: 0.0107 | X8: 0.0107 | Y8: 0.0106 | Z8: 0.0104 | AA8: 0.0103 | AB8: 0.01 | AC8: 0.01 | AD8: 0 | AE8: 0 | AF8: 0 | AG8: 0 | AH8: 0 | AI8: 0 | AJ8: 0 | AK8: 0 | AL8: 0 | AM8: 0 | AN8: 0 | AO8: 0 | AP8: 0 | AQ8: 0 | AR8: 0 | AS8: 0 | AT8: 0 | AU8: 0 | AV8: 0 | AW8: 0 | AX8: 0 | AY8: 0 | AZ8: 0 | BA8: 0 | BB8: 0 | BC8: 0 | BD8: 0 | BE8: 0 | BF8: 0 | BG8: 0 | BH8: 0 | BI8: 0 | BJ8: 0 | BK8: 0 | BL8: 0 | BM8: 0 | BN8: 0 | BO8: 0 | BP8: 0 | BQ8: 0 | BR8: 0 | BS8: 0 | BT8: 0 | BU8: 0 | BV8: 0 | BW8: 0 | BX8: 0 | BY8: 0 | BZ8: 0 | CA8: 0 | CB8: 0 | CC8: 0 | CD8: 0 | CE8: 0 | CF8: 0 | CG8: 0 | CH8: 0 | CI8: 0 | CJ8: 0 | CK8: 0 | CL8: 0 | CM8: 0 | CN8: 0 | CO8: 0 | CP8: 0 | CQ8: 0 | CR8: 0 | CS8: 0 | CT8: 0 | CU8: 0 | CV8: 0 | CW8: 0 | CX8: 0 | CY8: 0 | CZ8: 0 | DA8: 0 | DB8: 0 | DC8: 0 | DD8: 0 | DE8: 0 | DF8: 0 | DG8: 0 | DH8: 0 | DI8: 0 | DJ8: 0 | DK8: 0 | DL8: 0 | DM8: 0 | DN8: 0 | DO8: 0 | DP8: 0 | DQ8: 0 | DR8: 0 | DS8: 0 | DT8: 0 | DU8: 0 | DV8: 0 | DW8: 0 | DX8: 0 | DY8: 0 | DZ8: 0 | EA8: 0 | EB8: 0 | EC8: 0 | ED8: 0 | EE8: 0 | EF8: 0 | EG8: 0 | EH8: 0 | EI8: 0 | EJ8: 0 | EK8: 0 | EL8: 0 | EM8: 0 | EN8: 0 | EO8: 0 | EP8: 0 | EQ8: 0 | ER8: 0 | ES8: 0 | ET8: 0 | EU8: 0 | EV8: 0 | EW8: 0 | EX8: 0 | EY8: 0 | EZ8: 0 | FA8: 0 | FB8: 0 | FC8: 0 | FD8: 0 | FE8: 0 | FF8: 0 | FG8: 0 | FH8: 0 | FI8: 0 | FJ8: 0 | FK8: 0 | FL8: 0 | FM8: 0 | FN8: 0 | FO8: 0 | FP8: 0 | FQ8: 0 | FR8: 0 | FS8: 0 | FT8: 0 | FU8: 0 | FV8: 0 | FW8: 0 | FX8: 0 | FY8: 0 | FZ8: 0 | GA8: 0 | GB8: 0 | GC8: 0 | GD8: 0 | GE8: 0 | GF8: 0 | GG8: 0 | GH8: 0 | GI8: 0
A9: Feijão-Macassar (Fradinho) | B9: Alimentos | C9: 0 | D9: 0 | E9: 0 | F9: 0 | G9: 0 | H9: 0 | I9: 0 | J9: 0 | K9: 0 | L9: 0 | M9: 0 | N9: 0 | O9: 0 | P9: 0 | Q9: 0 | R9: 0 | S9: 0 | T9: 0 | U9: 0 | V9: 0 | W9: 0 | X9: 0 | Y9: 0 | Z9: 0 | AA9: 0 | AB9: 0 | AC9: 0 | AD9: 0.0314 | AE9: 0.0301 | AF9: 0.0299 | AG9: 0.0303 | AH9: 0.0304 | AI9: 0.0299 | AJ9: 0.0306 | AK9: 0.0326 | AL9: 0.0326 | AM9: 0.0301 | AN9: 0.0264 | AO9: 0.0261 | AP9: 0.0267 | AQ9: 0.0262 | AR9: 0.0267 | AS9: 0.0274 | AT9: 0.0274 | AU9: 0.0276 | AV9: 0.0276 | AW9: 0.0284 | AX9: 0.0304 | AY9: 0.0317 | AZ9: 0.0324 | BA9: 0.0338 | BB9: 0.0339 | BC9: 0.0349 | BD9: 0.036 | BE9: 0.0383 | BF9: 0.0404 | BG9: 0.0436 | BH9: 0.0466 | BI9: 0.0489 | BJ9: 0.0493 | BK9: 0.0489 | BL9: 0.0507 | BM9: 0.0512 | BN9: 0.0515 | BO9: 0.0534 | BP9: 0.0515 | BQ9: 0.0518 | BR9: 0.0467 | BS9: 0.041 | BT9: 0.0383 | BU9: 0.0383 | BV9: 0.0386 | BW9: 0.0383 | BX9: 0.0356 | BY9: 0.0348 | BZ9: 0.0329 | CA9: 0.0326 | CB9: 0.0328 | CC9: 0.0335 | CD9: 0.0348 | CE9: 0.0364 | CF9: 0.0381 | CG9: 0.0386 | CH9: 0.0375 | CI9: 0.0359 | CJ9: 0.0337 | CK9: 0.0315 | CL9: 0.0301 | CM9: 0.03 | CN9: 0.029 | CO9: 0.0306 | CP9: 0.0315 | CQ9: 0.034 | CR9: 0.0363 | CS9: 0.036 | CT9: 0.0331 | CU9: 0.0322 | CV9: 0.0307 | CW9: 0.0304 | CX9: 0.0298 | CY9: 0.0292 | CZ9: 0.0294 | DA9: 0.0301 | DB9: 0.0328 | DC9: 0.0342 | DD9: 0.0358 | DE9: 0.0367 | DF9: 0.0384 | DG9: 0.0355 | DH9: 0.0326 | DI9: 0.0323 | DJ9: 0.0314 | DK9: 0.0311 | DL9: 0.0304 | DM9: 0.0315 | DN9: 0.0332 | DO9: 0.0352 | DP9: 0.0375 | DQ9: 0.0359 | DR9: 0.0345 | DS9: 0.0342 | DT9: 0.034 | DU9: 0.0336 | DV9: 0.0171 | DW9: 0.0173 | DX9: 0.0171 | DY9: 0.017 | DZ9: 0.0174 | EA9: 0.0184 | EB9: 0.0198 | EC9: 0.0194 | ED9: 0.0197 | EE9: 0.021 | EF9: 0.0232 | EG9: 0.0234 | EH9: 0.0232 | EI9: 0.0218 | EJ9: 0.0182 | EK9: 0.0178 | EL9: 0.0178 | EM9: 0.0189 | EN9: 0.0205 | EO9: 0.0198 | EP9: 0.0169 | EQ9: 0.0163 | ER9: 0.0152 | ES9: 0.0147 | ET9: 0.0143 | EU9: 0.0147 | EV9: 0.0147 | EW9: 0.0153 | EX9: 0.0148 | EY9: 0.015 | EZ9: 0.0153 | FA9: 0.0152 | FB9: 0.0173 | FC9: 0.018 | FD9: 0.0192 | FE9: 0.0199 | FF9: 0.0199 | FG9: 0.0208 | FH9: 0.0185 | FI9: 0.0169 | FJ9: 0.0163 | FK9: 0.0168 | FL9: 0.0192 | FM9: 0.0257 | FN9: 0.0291 | FO9: 0.0314 | FP9: 0.0279 | FQ9: 0.0257 | FR9: 0.0212 | FS9: 0.0187 | FT9: 0.0174 | FU9: 0.0152 | FV9: 0.0151 | FW9: 0.0155 | FX9: 0.016 | FY9: 0.0168 | FZ9: 0.0162 | GA9: 0.0158 | GB9: 0.0164 | GC9: 0.0169 | GD9: 0.0165 | GE9: 0.0166 | GF9: 0.016 | GG9: 0.0152 | GH9: 0.0156 | GI9: 0.0165
A10: Feijão-Branco | B10: Alimentos | C10: 0 | D10: 0 | E10: 0 | F10: 0 | G10: 0 | H10: 0 | I10: 0 | J10: 0 | K10: 0 | L10: 0 | M10: 0 | N10: 0 | O10: 0 | P10: 0 | Q10: 0 | R10: 0 | S10: 0 | T10: 0 | U10: 0 | V10: 0 | W10: 0 | X10: 0 | Y10: 0 | Z10: 0 | AA10: 0 | AB10: 0 | AC10: 0 | AD10: 0.0024 | AE10: 0.0023 | AF10: 0.0021 | AG10: 0.0021 | AH10: 0.002 | AI10: 0.0021 | AJ10: 0.0023 | AK10: 0.0026 | AL10: 0.0025 | AM10: 0.002 | AN10: 0.0016 | AO10: 0.0013 | AP10: 0.0015 | AQ10: 0.0015 | AR10: 0.0016 | AS10: 0.0016 | AT10: 0.0015 | AU10: 0.0016 | AV10: 0.0016 | AW10: 0.0016 | AX10: 0 | AY10: 0 | AZ10: 0 | BA10: 0 | BB10: 0 | BC10: 0 | BD10: 0 | BE10: 0 | BF10: 0 | BG10: 0 | BH10: 0 | BI10: 0 | BJ10: 0 | BK10: 0 | BL10: 0 | BM10: 0 | BN10: 0 | BO10: 0 | BP10: 0 | BQ10: 0 | BR10: 0 | BS10: 0 | BT10: 0 | BU10: 0 | BV10: 0 | BW10: 0 | BX10: 0 | BY10: 0 | BZ10: 0 | CA10: 0 | CB10: 0 | CC10: 0 | CD10: 0 | CE10: 0 | CF10: 0 | CG10: 0 | CH10: 0 | CI10: 0 | CJ10: 0 | CK10: 0 | CL10: 0 | CM10: 0 | CN10: 0 | CO10: 0 | CP10: 0 | CQ10: 0 | CR10: 0 | CS10: 0 | CT10: 0 | CU10: 0 | CV10: 0 | CW10: 0 | CX10: 0 | CY10: 0 | CZ10: 0 | DA10: 0 | DB10: 0 | DC10: 0 | DD10: 0 | DE10: 0 | DF10: 0 | DG10: 0 | DH10: 0 | DI10: 0 | DJ10: 0 | DK10: 0 | DL10: 0 | DM10: 0 | DN10: 0 | DO10: 0 | DP10: 0 | DQ10: 0 | DR10: 0 | DS10: 0 | DT10: 0 | DU10: 0 | DV10: 0 | DW10: 0 | DX10: 0 | DY10: 0 | DZ10: 0 | EA10: 0 | EB10: 0 | EC10: 0 | ED10: 0 | EE10: 0 | EF10: 0 | EG10: 0 | EH10: 0 | EI10: 0 | EJ10: 0 | EK10: 0 | EL10: 0 | EM10: 0 | EN10: 0 | EO10: 0 | EP10: 0 | EQ10: 0 | ER10: 0 | ES10: 0 | ET10: 0 | EU10: 0 | EV10: 0 | EW10: 0 | EX10: 0 | EY10: 0 | EZ10: 0 | FA10: 0 | FB10: 0 | FC10: 0 | FD10: 0 | FE10: 0 | FF10: 0 | FG10: 0 | FH10: 0 | FI10: 0 | FJ10: 0 | FK10: 0 | FL10: 0 | FM10: 0 | FN10: 0 | FO10: 0 | FP10: 0 | FQ10: 0 | FR10: 0 | FS10: 0 | FT10: 0 | FU10: 0 | FV10: 0 | FW10: 0 | FX10: 0 | FY10: 0 | FZ10: 0 | GA10: 0 | GB10: 0 | GC10: 0 | GD10: 0 | GE10: 0 | GF10: 0 | GG10: 0 | GH10: 0 | GI10: 0
A11: Fava | B11: Alimentos | C11: 0 | D11: 0 | E11: 0 | F11: 0 | G11: 0 | H11: 0 | I11: 0 | J11: 0 | K11: 0 | L11: 0 | M11: 0 | N11: 0 | O11: 0 | P11: 0 | Q11: 0 | R11: 0 | S11: 0 | T11: 0 | U11: 0 | V11: 0 | W11: 0 | X11: 0 | Y11: 0 | Z11: 0 | AA11: 0 | AB11: 0 | AC11: 0 | AD11: 0 | AE11: 0 | AF11: 0 | AG11: 0 | AH11: 0 | AI11: 0 | AJ11: 0 | AK11: 0 | AL11: 0 | AM11: 0 | AN11: 0 | AO11: 0 | AP11: 0 | AQ11: 0 | AR11: 0 | AS11: 0 | AT11: 0 | AU11: 0 | AV11: 0 | AW11: 0 | AX11: 0 | AY11: 0 | AZ11: 0 | BA11: 0 | BB11: 0 | BC11: 0 | BD11: 0 | BE11: 0 | BF11: 0 | BG11: 0 | BH11: 0 | BI11: 0 | BJ11: 0 | BK11: 0 | BL11: 0 | BM11: 0 | BN11: 0 | BO11: 0 | BP11: 0 | BQ11: 0 | BR11: 0 | BS11: 0 | BT11: 0 | BU11: 0 | BV11: 0 | BW11: 0 | BX11: 0 | BY11: 0 | BZ11: 0 | CA11: 0 | CB11: 0 | CC11: 0 | CD11: 0 | CE11: 0 | CF11: 0 | CG11: 0 | CH11: 0 | CI11: 0 | CJ11: 0 | CK11: 0 | CL11: 0 | CM11: 0 | CN11: 0 | CO11: 0 | CP11: 0 | CQ11: 0 | CR11: 0 | CS11: 0 | CT11: 0 | CU11: 0 | CV11: 0 | CW11: 0 | CX11: 0 | CY11: 0 | CZ11: 0 | DA11: 0 | DB11: 0 | DC11: 0 | DD11: 0 | DE11: 0 | DF11: 0 | DG11: 0 | DH11: 0 | DI11: 0 | DJ11: 0 | DK11: 0 | DL11: 0 | DM11: 0 | DN11: 0 | DO11: 0 | DP11: 0 | DQ11: 0 | DR11: 0 | DS11: 0 | DT11: 0 | DU11: 0 | DV11: 0.0045 | DW11: 0.0045 | DX11: 0.0044 | DY11: 0.0041 | DZ11: 0.0042 | EA11: 0.0039 | EB11: 0.0041 | EC11: 0.0042 | ED11: 0.004 | EE11: 0.0039 | EF11: 0.0038 | EG11: 0.0041 | EH11: 0.0034 | EI11: 0.0034 | EJ11: 0.0033 | EK11: 0.0031 | EL11: 0.003 | EM11: 0.0028 | EN11: 0.0028 | EO11: 0.0026 | EP11: 0.0028 | EQ11: 0.0028 | ER11: 0.0027 | ES11: 0.0029 | ET11: 0.003 | EU11: 0.0029 | EV11: 0.003 | EW11: 0.0031 | EX11: 0.0032 | EY11: 0.0031 | EZ11: 0.0032 | FA11: 0.0034 | FB11: 0.0035 | FC11: 0.0035 | FD11: 0.0036 | FE11: 0.0037 | FF11: 0.0038 | FG11: 0.0038 | FH11: 0.0038 | FI11: 0.0037 | FJ11: 0.0038 | FK11: 0.0038 | FL11: 0.0038 | FM11: 0.0038 | FN11: 0.0037 | FO11: 0.0035 | FP11: 0.0033 | FQ11: 0.0031 | FR11: 0.0029 | FS11: 0.0029 | FT11: 0.003 | FU11: 0.0029 | FV11: 0.0029 | FW11: 0.0029 | FX11: 0.0029 | FY11: 0.0029 | FZ11: 0.0029 | GA11: 0.0028 | GB11: 0.0028 | GC11: 0.0028 | GD11: 0.0027 | GE11: 0.0027 | GF11: 0.0027 | GG11: 0.0027 | GH11: 0.0027 | GI11: 0.0027
A12: Farinha De Arroz | B12: Alimentos | C12: 0.0024 | D12: 0.0024 | E12: 0.0023 | F12: 0.0024 | G12: 0.0025 | H12: 0.0024 | I12: 0.0024 | J12: 0.0024 | K12: 0.0024 | L12: 0.0024 | M12: 0.0025 | N12: 0.0026 | O12: 0.0027 | P12: 0.0027 | Q12: 0.0028 | R12: 0.0028 | S12: 0.0028 | T12: 0.0027 | U12: 0.0027 | V12: 0.0027 | W12: 0.0028 | X12: 0.0028 | Y12: 0.0028 | Z12: 0.0028 | AA12: 0.0026 | AB12: 0.0028 | AC12: 0.0028 | AD12: 0.0117 | AE12: 0.0118 | AF12: 0.0118 | AG12: 0.0117 | AH12: 0.0115 | AI12: 0.012 | AJ12: 0.0123 | AK12: 0.0126 | AL12: 0.0124 | AM12: 0.0131 | AN12: 0.0131 | AO12: 0.0129 | AP12: 0.0128 | AQ12: 0.0126 | AR12: 0.0126 | AS12: 0.0127 | AT12: 0.0126 | AU12: 0.0126 | AV12: 0.0127 | AW12: 0.0128 | AX12: 0.0122 | AY12: 0.012 | AZ12: 0.0119 | BA12: 0.0118 | BB12: 0.012 | BC12: 0.0118 | BD12: 0.0118 | BE12: 0.0119 | BF12: 0.0118 | BG12: 0.0112 | BH12: 0.0113 | BI12: 0.0107 | BJ12: 0.0106 | BK12: 0.0106 | BL12: 0.0107 | BM12: 0.0107 | BN12: 0.0106 | BO12: 0.0106 | BP12: 0.0106 | BQ12: 0.0106 | BR12: 0.0105 | BS12: 0.0106 | BT12: 0.0106 | BU12: 0.0106 | BV12: 0.0108 | BW12: 0.0108 | BX12: 0.0108 | BY12: 0.0111 | BZ12: 0.0113 | CA12: 0.0114 | CB12: 0.0113 | CC12: 0.0116 | CD12: 0.0116 | CE12: 0.0118 | CF12: 0.0118 | CG12: 0.0121 | CH12: 0.0119 | CI12: 0.0118 | CJ12: 0.0117 | CK12: 0.0114 | CL12: 0.0114 | CM12: 0.012 | CN12: 0.0124 | CO12: 0.0128 | CP12: 0.0125 | CQ12: 0.0122 | CR12: 0.0122 | CS12: 0.0122 | CT12: 0.0124 | CU12: 0.0122 | CV12: 0.0122 | CW12: 0.0125 | CX12: 0.0125 | CY12: 0.0127 | CZ12: 0.0126 | DA12: 0.0126 | DB12: 0.0125 | DC12: 0.0122 | DD12: 0.0117 | DE12: 0.0114 | DF12: 0.0113 | DG12: 0.0113 | DH12: 0.0114 | DI12: 0.0112 | DJ12: 0.0112 | DK12: 0.0113 | DL12: 0.0114 | DM12: 0.0113 | DN12: 0.0114 | DO12: 0.0111 | DP12: 0.0109 | DQ12: 0.0111 | DR12: 0.0107 | DS12: 0.0107 | DT12: 0.0108 | DU12: 0.0109 | DV12: 0.0085 | DW12: 0.0086 | DX12: 0.0085 | DY12: 0.0085 | DZ12: 0.0086 | EA12: 0.0087 | EB12: 0.0087 | EC12: 0.0085 | ED12: 0.0084 | EE12: 0.0085 | EF12: 0.0086 | EG12: 0.0088 | EH12: 0.0086 | EI12: 0.0086 | EJ12: 0.0087 | EK12: 0.0086 | EL12: 0.0087 | EM12: 0.0088 | EN12: 0.0088 | EO12: 0.0087 | EP12: 0.0087 | EQ12: 0.0088 | ER12: 0.009 | ES12: 0.0088 | ET12: 0.009 | EU12: 0.0089 | EV12: 0.009 | EW12: 0.009 | EX12: 0.0091 | EY12: 0.0089 | EZ12: 0.0087 | FA12: 0.0085 | FB12: 0.0086 | FC12: 0.0086 | FD12: 0.0086 | FE12: 0.0085 | FF12: 0.0086 | FG12: 0.0085 | FH12: 0.0083 | FI12: 0.0083 | FJ12: 0.0082 | FK12: 0.0082 | FL12: 0.0082 | FM12: 0.0079 | FN12: 0.008 | FO12: 0.008 | FP12: 0.0082 | FQ12: 0.0081 | FR12: 0.0083 | FS12: 0.0084 | FT12: 0.0085 | FU12: 0.0086 | FV12: 0.0086 | FW12: 0.0085 | FX12: 0.0085 | FY12: 0.0084 | FZ12: 0.0085 | GA12: 0.0083 | GB12: 0.0083 | GC12: 0.0083 | GD12: 0.0083 | GE12: 0.0084 | GF12: 0.0083 | GG12: 0.0083 | GH12: 0.0084 | GI12: 0.0082
